Workbook

Sheet Summary
A1: Deliveries in and out: summary
A2: Sample Distribution · Wacol DC · SAMPLE DATA (invented) · The Fourth Sheet · Made with Python (openpyxl)
A3: Data status (data retrieved 2pm, Tue 6 Oct 2026): today's deliveries are incomplete; 1–5 October is provisional (until October is locked); September and earlier are locked. Generated 22 Oct 2026, 7:51pm.
A5: Deliveries out, to customers
A6: Period | B6: From | C6: To | D6: Due in period | E6: On time | F6: Late | G6: Very late | H6: Overdue now | I6: Not due yet / on its way | J6: On time % | K6: In full %
A7: Today, Tue 6 Oct (as at 2pm) | B7: 46301 | C7: 46301 | D7: =COUNTIFS('Deliveries out'!$H:$H,">="&$B7,'Deliveries out'!$H:$H,"<="&$C7) | E7: =COUNTIFS('Deliveries out'!$H:$H,">="&$B7,'Deliveries out'!$H:$H,"<="&$C7,'Deliveries out'!$K:$K,"On time") | F7: =COUNTIFS('Deliveries out'!$H:$H,">="&$B7,'Deliveries out'!$H:$H,"<="&$C7,'Deliveries out'!$K:$K,"Late") | G7: =COUNTIFS('Deliveries out'!$H:$H,">="&$B7,'Deliveries out'!$H:$H,"<="&$C7,'Deliveries out'!$K:$K,"Very late") | H7: =COUNTIFS('Deliveries out'!$H:$H,">="&$B7,'Deliveries out'!$H:$H,"<="&$C7,'Deliveries out'!$K:$K,"Overdue") | I7: =COUNTIFS('Deliveries out'!$H:$H,">="&$B7,'Deliveries out'!$H:$H,"<="&$C7,'Deliveries out'!$K:$K,"In transit") | J7: =IF(SUM(E7:H7)=0,"",E7/SUM(E7:H7)) | K7: =IF(SUM(E7:G7)=0,"",SUMIFS('Deliveries out'!$P:$P,'Deliveries out'!$H:$H,">="&$B7,'Deliveries out'!$H:$H,"<="&$C7,'Deliveries out'!$Q:$Q,1)/SUM(E7:G7))
A8: Fri 2 Oct (last working day) | B8: 46297 | C8: 46297 | D8: =COUNTIFS('Deliveries out'!$H:$H,">="&$B8,'Deliveries out'!$H:$H,"<="&$C8) | E8: =COUNTIFS('Deliveries out'!$H:$H,">="&$B8,'Deliveries out'!$H:$H,"<="&$C8,'Deliveries out'!$K:$K,"On time") | F8: =COUNTIFS('Deliveries out'!$H:$H,">="&$B8,'Deliveries out'!$H:$H,"<="&$C8,'Deliveries out'!$K:$K,"Late") | G8: =COUNTIFS('Deliveries out'!$H:$H,">="&$B8,'Deliveries out'!$H:$H,"<="&$C8,'Deliveries out'!$K:$K,"Very late") | H8: =COUNTIFS('Deliveries out'!$H:$H,">="&$B8,'Deliveries out'!$H:$H,"<="&$C8,'Deliveries out'!$K:$K,"Overdue") | I8: =COUNTIFS('Deliveries out'!$H:$H,">="&$B8,'Deliveries out'!$H:$H,"<="&$C8,'Deliveries out'!$K:$K,"In transit") | J8: =IF(SUM(E8:H8)=0,"",E8/SUM(E8:H8)) | K8: =IF(SUM(E8:G8)=0,"",SUMIFS('Deliveries out'!$P:$P,'Deliveries out'!$H:$H,">="&$B8,'Deliveries out'!$H:$H,"<="&$C8,'Deliveries out'!$Q:$Q,1)/SUM(E8:G8))
A9: Last 7 days (30 Sep to 6 Oct) | B9: 46295 | C9: 46301 | D9: =COUNTIFS('Deliveries out'!$H:$H,">="&$B9,'Deliveries out'!$H:$H,"<="&$C9) | E9: =COUNTIFS('Deliveries out'!$H:$H,">="&$B9,'Deliveries out'!$H:$H,"<="&$C9,'Deliveries out'!$K:$K,"On time") | F9: =COUNTIFS('Deliveries out'!$H:$H,">="&$B9,'Deliveries out'!$H:$H,"<="&$C9,'Deliveries out'!$K:$K,"Late") | G9: =COUNTIFS('Deliveries out'!$H:$H,">="&$B9,'Deliveries out'!$H:$H,"<="&$C9,'Deliveries out'!$K:$K,"Very late") | H9: =COUNTIFS('Deliveries out'!$H:$H,">="&$B9,'Deliveries out'!$H:$H,"<="&$C9,'Deliveries out'!$K:$K,"Overdue") | I9: =COUNTIFS('Deliveries out'!$H:$H,">="&$B9,'Deliveries out'!$H:$H,"<="&$C9,'Deliveries out'!$K:$K,"In transit") | J9: =IF(SUM(E9:H9)=0,"",E9/SUM(E9:H9)) | K9: =IF(SUM(E9:G9)=0,"",SUMIFS('Deliveries out'!$P:$P,'Deliveries out'!$H:$H,">="&$B9,'Deliveries out'!$H:$H,"<="&$C9,'Deliveries out'!$Q:$Q,1)/SUM(E9:G9))
A10: Last 30 days (7 Sep to 6 Oct) | B10: 46272 | C10: 46301 | D10: =COUNTIFS('Deliveries out'!$H:$H,">="&$B10,'Deliveries out'!$H:$H,"<="&$C10) | E10: =COUNTIFS('Deliveries out'!$H:$H,">="&$B10,'Deliveries out'!$H:$H,"<="&$C10,'Deliveries out'!$K:$K,"On time") | F10: =COUNTIFS('Deliveries out'!$H:$H,">="&$B10,'Deliveries out'!$H:$H,"<="&$C10,'Deliveries out'!$K:$K,"Late") | G10: =COUNTIFS('Deliveries out'!$H:$H,">="&$B10,'Deliveries out'!$H:$H,"<="&$C10,'Deliveries out'!$K:$K,"Very late") | H10: =COUNTIFS('Deliveries out'!$H:$H,">="&$B10,'Deliveries out'!$H:$H,"<="&$C10,'Deliveries out'!$K:$K,"Overdue") | I10: =COUNTIFS('Deliveries out'!$H:$H,">="&$B10,'Deliveries out'!$H:$H,"<="&$C10,'Deliveries out'!$K:$K,"In transit") | J10: =IF(SUM(E10:H10)=0,"",E10/SUM(E10:H10)) | K10: =IF(SUM(E10:G10)=0,"",SUMIFS('Deliveries out'!$P:$P,'Deliveries out'!$H:$H,">="&$B10,'Deliveries out'!$H:$H,"<="&$C10,'Deliveries out'!$Q:$Q,1)/SUM(E10:G10))
A13: Deliveries in, from suppliers
A14: Period | B14: From | C14: To | D14: Due in period | E14: On time | F14: Late | G14: Very late | H14: Overdue now | I14: Not due yet / on its way | J14: On time % | K14: In full %
A15: Today, Tue 6 Oct (as at 2pm) | B15: 46301 | C15: 46301 | D15: =COUNTIFS('Deliveries in'!$G:$G,">="&$B15,'Deliveries in'!$G:$G,"<="&$C15) | E15: =COUNTIFS('Deliveries in'!$G:$G,">="&$B15,'Deliveries in'!$G:$G,"<="&$C15,'Deliveries in'!$I:$I,"On time") | F15: =COUNTIFS('Deliveries in'!$G:$G,">="&$B15,'Deliveries in'!$G:$G,"<="&$C15,'Deliveries in'!$I:$I,"Late") | G15: =COUNTIFS('Deliveries in'!$G:$G,">="&$B15,'Deliveries in'!$G:$G,"<="&$C15,'Deliveries in'!$I:$I,"Very late") | H15: =COUNTIFS('Deliveries in'!$G:$G,">="&$B15,'Deliveries in'!$G:$G,"<="&$C15,'Deliveries in'!$I:$I,"Overdue") | I15: =COUNTIFS('Deliveries in'!$G:$G,">="&$B15,'Deliveries in'!$G:$G,"<="&$C15,'Deliveries in'!$I:$I,"Due") | J15: =IF(SUM(E15:H15)=0,"",E15/SUM(E15:H15)) | K15: =IF(SUM(E15:G15)=0,"",SUMIFS('Deliveries in'!$P:$P,'Deliveries in'!$G:$G,">="&$B15,'Deliveries in'!$G:$G,"<="&$C15,'Deliveries in'!$O:$O,1)/SUM(E15:G15))
A16: Fri 2 Oct (last working day) | B16: 46297 | C16: 46297 | D16: =COUNTIFS('Deliveries in'!$G:$G,">="&$B16,'Deliveries in'!$G:$G,"<="&$C16) | E16: =COUNTIFS('Deliveries in'!$G:$G,">="&$B16,'Deliveries in'!$G:$G,"<="&$C16,'Deliveries in'!$I:$I,"On time") | F16: =COUNTIFS('Deliveries in'!$G:$G,">="&$B16,'Deliveries in'!$G:$G,"<="&$C16,'Deliveries in'!$I:$I,"Late") | G16: =COUNTIFS('Deliveries in'!$G:$G,">="&$B16,'Deliveries in'!$G:$G,"<="&$C16,'Deliveries in'!$I:$I,"Very late") | H16: =COUNTIFS('Deliveries in'!$G:$G,">="&$B16,'Deliveries in'!$G:$G,"<="&$C16,'Deliveries in'!$I:$I,"Overdue") | I16: =COUNTIFS('Deliveries in'!$G:$G,">="&$B16,'Deliveries in'!$G:$G,"<="&$C16,'Deliveries in'!$I:$I,"Due") | J16: =IF(SUM(E16:H16)=0,"",E16/SUM(E16:H16)) | K16: =IF(SUM(E16:G16)=0,"",SUMIFS('Deliveries in'!$P:$P,'Deliveries in'!$G:$G,">="&$B16,'Deliveries in'!$G:$G,"<="&$C16,'Deliveries in'!$O:$O,1)/SUM(E16:G16))
A17: Last 7 days (30 Sep to 6 Oct) | B17: 46295 | C17: 46301 | D17: =COUNTIFS('Deliveries in'!$G:$G,">="&$B17,'Deliveries in'!$G:$G,"<="&$C17) | E17: =COUNTIFS('Deliveries in'!$G:$G,">="&$B17,'Deliveries in'!$G:$G,"<="&$C17,'Deliveries in'!$I:$I,"On time") | F17: =COUNTIFS('Deliveries in'!$G:$G,">="&$B17,'Deliveries in'!$G:$G,"<="&$C17,'Deliveries in'!$I:$I,"Late") | G17: =COUNTIFS('Deliveries in'!$G:$G,">="&$B17,'Deliveries in'!$G:$G,"<="&$C17,'Deliveries in'!$I:$I,"Very late") | H17: =COUNTIFS('Deliveries in'!$G:$G,">="&$B17,'Deliveries in'!$G:$G,"<="&$C17,'Deliveries in'!$I:$I,"Overdue") | I17: =COUNTIFS('Deliveries in'!$G:$G,">="&$B17,'Deliveries in'!$G:$G,"<="&$C17,'Deliveries in'!$I:$I,"Due") | J17: =IF(SUM(E17:H17)=0,"",E17/SUM(E17:H17)) | K17: =IF(SUM(E17:G17)=0,"",SUMIFS('Deliveries in'!$P:$P,'Deliveries in'!$G:$G,">="&$B17,'Deliveries in'!$G:$G,"<="&$C17,'Deliveries in'!$O:$O,1)/SUM(E17:G17))
A18: Last 30 days (7 Sep to 6 Oct) | B18: 46272 | C18: 46301 | D18: =COUNTIFS('Deliveries in'!$G:$G,">="&$B18,'Deliveries in'!$G:$G,"<="&$C18) | E18: =COUNTIFS('Deliveries in'!$G:$G,">="&$B18,'Deliveries in'!$G:$G,"<="&$C18,'Deliveries in'!$I:$I,"On time") | F18: =COUNTIFS('Deliveries in'!$G:$G,">="&$B18,'Deliveries in'!$G:$G,"<="&$C18,'Deliveries in'!$I:$I,"Late") | G18: =COUNTIFS('Deliveries in'!$G:$G,">="&$B18,'Deliveries in'!$G:$G,"<="&$C18,'Deliveries in'!$I:$I,"Very late") | H18: =COUNTIFS('Deliveries in'!$G:$G,">="&$B18,'Deliveries in'!$G:$G,"<="&$C18,'Deliveries in'!$I:$I,"Overdue") | I18: =COUNTIFS('Deliveries in'!$G:$G,">="&$B18,'Deliveries in'!$G:$G,"<="&$C18,'Deliveries in'!$I:$I,"Due") | J18: =IF(SUM(E18:H18)=0,"",E18/SUM(E18:H18)) | K18: =IF(SUM(E18:G18)=0,"",SUMIFS('Deliveries in'!$P:$P,'Deliveries in'!$G:$G,">="&$B18,'Deliveries in'!$G:$G,"<="&$C18,'Deliveries in'!$O:$O,1)/SUM(E18:G18))
A21: Late by carrier and region, last 30 days
A22: From | B22: 46272 | C22: 46301
A23: Carrier · region | B23: Carrier | C23: Region | D23: Due in period | E23: Late, very late or overdue | F23: % late
A24: Carrier A · Gold Coast | B24: Carrier A | C24: Gold Coast | D24: =COUNTIFS('Deliveries out'!$H:$H,">="&$B$22,'Deliveries out'!$H:$H,"<="&$C$22,'Deliveries out'!$F:$F,$B24,'Deliveries out'!$E:$E,$C24) | E24: =COUNTIFS('Deliveries out'!$H:$H,">="&$B$22,'Deliveries out'!$H:$H,"<="&$C$22,'Deliveries out'!$F:$F,$B24,'Deliveries out'!$E:$E,$C24,'Deliveries out'!$K:$K,"Late")+COUNTIFS('Deliveries out'!$H:$H,">="&$B$22,'Deliveries out'!$H:$H,"<="&$C$22,'Deliveries out'!$F:$F,$B24,'Deliveries out'!$E:$E,$C24,'Deliveries out'!$K:$K,"Very late")+COUNTIFS('Deliveries out'!$H:$H,">="&$B$22,'Deliveries out'!$H:$H,"<="&$C$22,'Deliveries out'!$F:$F,$B24,'Deliveries out'!$E:$E,$C24,'Deliveries out'!$K:$K,"Overdue") | F24: =IF(D24=0,"",E24/D24)
A25: Carrier B · Moreton Bay | B25: Carrier B | C25: Moreton Bay | D25: =COUNTIFS('Deliveries out'!$H:$H,">="&$B$22,'Deliveries out'!$H:$H,"<="&$C$22,'Deliveries out'!$F:$F,$B25,'Deliveries out'!$E:$E,$C25) | E25: =COUNTIFS('Deliveries out'!$H:$H,">="&$B$22,'Deliveries out'!$H:$H,"<="&$C$22,'Deliveries out'!$F:$F,$B25,'Deliveries out'!$E:$E,$C25,'Deliveries out'!$K:$K,"Late")+COUNTIFS('Deliveries out'!$H:$H,">="&$B$22,'Deliveries out'!$H:$H,"<="&$C$22,'Deliveries out'!$F:$F,$B25,'Deliveries out'!$E:$E,$C25,'Deliveries out'!$K:$K,"Very late")+COUNTIFS('Deliveries out'!$H:$H,">="&$B$22,'Deliveries out'!$H:$H,"<="&$C$22,'Deliveries out'!$F:$F,$B25,'Deliveries out'!$E:$E,$C25,'Deliveries out'!$K:$K,"Overdue") | F25: =IF(D25=0,"",E25/D25)
A26: Carrier A · Logan | B26: Carrier A | C26: Logan | D26: =COUNTIFS('Deliveries out'!$H:$H,">="&$B$22,'Deliveries out'!$H:$H,"<="&$C$22,'Deliveries out'!$F:$F,$B26,'Deliveries out'!$E:$E,$C26) | E26: =COUNTIFS('Deliveries out'!$H:$H,">="&$B$22,'Deliveries out'!$H:$H,"<="&$C$22,'Deliveries out'!$F:$F,$B26,'Deliveries out'!$E:$E,$C26,'Deliveries out'!$K:$K,"Late")+COUNTIFS('Deliveries out'!$H:$H,">="&$B$22,'Deliveries out'!$H:$H,"<="&$C$22,'Deliveries out'!$F:$F,$B26,'Deliveries out'!$E:$E,$C26,'Deliveries out'!$K:$K,"Very late")+COUNTIFS('Deliveries out'!$H:$H,">="&$B$22,'Deliveries out'!$H:$H,"<="&$C$22,'Deliveries out'!$F:$F,$B26,'Deliveries out'!$E:$E,$C26,'Deliveries out'!$K:$K,"Overdue") | F26: =IF(D26=0,"",E26/D26)
A27: Own trucks · Brisbane South | B27: Own trucks | C27: Brisbane South | D27: =COUNTIFS('Deliveries out'!$H:$H,">="&$B$22,'Deliveries out'!$H:$H,"<="&$C$22,'Deliveries out'!$F:$F,$B27,'Deliveries out'!$E:$E,$C27) | E27: =COUNTIFS('Deliveries out'!$H:$H,">="&$B$22,'Deliveries out'!$H:$H,"<="&$C$22,'Deliveries out'!$F:$F,$B27,'Deliveries out'!$E:$E,$C27,'Deliveries out'!$K:$K,"Late")+COUNTIFS('Deliveries out'!$H:$H,">="&$B$22,'Deliveries out'!$H:$H,"<="&$C$22,'Deliveries out'!$F:$F,$B27,'Deliveries out'!$E:$E,$C27,'Deliveries out'!$K:$K,"Very late")+COUNTIFS('Deliveries out'!$H:$H,">="&$B$22,'Deliveries out'!$H:$H,"<="&$C$22,'Deliveries out'!$F:$F,$B27,'Deliveries out'!$E:$E,$C27,'Deliveries out'!$K:$K,"Overdue") | F27: =IF(D27=0,"",E27/D27)
A28: Carrier B · Sunshine Coast | B28: Carrier B | C28: Sunshine Coast | D28: =COUNTIFS('Deliveries out'!$H:$H,">="&$B$22,'Deliveries out'!$H:$H,"<="&$C$22,'Deliveries out'!$F:$F,$B28,'Deliveries out'!$E:$E,$C28) | E28: =COUNTIFS('Deliveries out'!$H:$H,">="&$B$22,'Deliveries out'!$H:$H,"<="&$C$22,'Deliveries out'!$F:$F,$B28,'Deliveries out'!$E:$E,$C28,'Deliveries out'!$K:$K,"Late")+COUNTIFS('Deliveries out'!$H:$H,">="&$B$22,'Deliveries out'!$H:$H,"<="&$C$22,'Deliveries out'!$F:$F,$B28,'Deliveries out'!$E:$E,$C28,'Deliveries out'!$K:$K,"Very late")+COUNTIFS('Deliveries out'!$H:$H,">="&$B$22,'Deliveries out'!$H:$H,"<="&$C$22,'Deliveries out'!$F:$F,$B28,'Deliveries out'!$E:$E,$C28,'Deliveries out'!$K:$K,"Overdue") | F28: =IF(D28=0,"",E28/D28)
A29: Own trucks · Inner Brisbane | B29: Own trucks | C29: Inner Brisbane | D29: =COUNTIFS('Deliveries out'!$H:$H,">="&$B$22,'Deliveries out'!$H:$H,"<="&$C$22,'Deliveries out'!$F:$F,$B29,'Deliveries out'!$E:$E,$C29) | E29: =COUNTIFS('Deliveries out'!$H:$H,">="&$B$22,'Deliveries out'!$H:$H,"<="&$C$22,'Deliveries out'!$F:$F,$B29,'Deliveries out'!$E:$E,$C29,'Deliveries out'!$K:$K,"Late")+COUNTIFS('Deliveries out'!$H:$H,">="&$B$22,'Deliveries out'!$H:$H,"<="&$C$22,'Deliveries out'!$F:$F,$B29,'Deliveries out'!$E:$E,$C29,'Deliveries out'!$K:$K,"Very late")+COUNTIFS('Deliveries out'!$H:$H,">="&$B$22,'Deliveries out'!$H:$H,"<="&$C$22,'Deliveries out'!$F:$F,$B29,'Deliveries out'!$E:$E,$C29,'Deliveries out'!$K:$K,"Overdue") | F29: =IF(D29=0,"",E29/D29)
A30: Carrier B · Toowoomba | B30: Carrier B | C30: Toowoomba | D30: =COUNTIFS('Deliveries out'!$H:$H,">="&$B$22,'Deliveries out'!$H:$H,"<="&$C$22,'Deliveries out'!$F:$F,$B30,'Deliveries out'!$E:$E,$C30) | E30: =COUNTIFS('Deliveries out'!$H:$H,">="&$B$22,'Deliveries out'!$H:$H,"<="&$C$22,'Deliveries out'!$F:$F,$B30,'Deliveries out'!$E:$E,$C30,'Deliveries out'!$K:$K,"Late")+COUNTIFS('Deliveries out'!$H:$H,">="&$B$22,'Deliveries out'!$H:$H,"<="&$C$22,'Deliveries out'!$F:$F,$B30,'Deliveries out'!$E:$E,$C30,'Deliveries out'!$K:$K,"Very late")+COUNTIFS('Deliveries out'!$H:$H,">="&$B$22,'Deliveries out'!$H:$H,"<="&$C$22,'Deliveries out'!$F:$F,$B30,'Deliveries out'!$E:$E,$C30,'Deliveries out'!$K:$K,"Overdue") | F30: =IF(D30=0,"",E30/D30)
A31: Own trucks · Brisbane West | B31: Own trucks | C31: Brisbane West | D31: =COUNTIFS('Deliveries out'!$H:$H,">="&$B$22,'Deliveries out'!$H:$H,"<="&$C$22,'Deliveries out'!$F:$F,$B31,'Deliveries out'!$E:$E,$C31) | E31: =COUNTIFS('Deliveries out'!$H:$H,">="&$B$22,'Deliveries out'!$H:$H,"<="&$C$22,'Deliveries out'!$F:$F,$B31,'Deliveries out'!$E:$E,$C31,'Deliveries out'!$K:$K,"Late")+COUNTIFS('Deliveries out'!$H:$H,">="&$B$22,'Deliveries out'!$H:$H,"<="&$C$22,'Deliveries out'!$F:$F,$B31,'Deliveries out'!$E:$E,$C31,'Deliveries out'!$K:$K,"Very late")+COUNTIFS('Deliveries out'!$H:$H,">="&$B$22,'Deliveries out'!$H:$H,"<="&$C$22,'Deliveries out'!$F:$F,$B31,'Deliveries out'!$E:$E,$C31,'Deliveries out'!$K:$K,"Overdue") | F31: =IF(D31=0,"",E31/D31)
A32: Own trucks · Brisbane East | B32: Own trucks | C32: Brisbane East | D32: =COUNTIFS('Deliveries out'!$H:$H,">="&$B$22,'Deliveries out'!$H:$H,"<="&$C$22,'Deliveries out'!$F:$F,$B32,'Deliveries out'!$E:$E,$C32) | E32: =COUNTIFS('Deliveries out'!$H:$H,">="&$B$22,'Deliveries out'!$H:$H,"<="&$C$22,'Deliveries out'!$F:$F,$B32,'Deliveries out'!$E:$E,$C32,'Deliveries out'!$K:$K,"Late")+COUNTIFS('Deliveries out'!$H:$H,">="&$B$22,'Deliveries out'!$H:$H,"<="&$C$22,'Deliveries out'!$F:$F,$B32,'Deliveries out'!$E:$E,$C32,'Deliveries out'!$K:$K,"Very late")+COUNTIFS('Deliveries out'!$H:$H,">="&$B$22,'Deliveries out'!$H:$H,"<="&$C$22,'Deliveries out'!$F:$F,$B32,'Deliveries out'!$E:$E,$C32,'Deliveries out'!$K:$K,"Overdue") | F32: =IF(D32=0,"",E32/D32)
A33: Own trucks · Brisbane North | B33: Own trucks | C33: Brisbane North | D33: =COUNTIFS('Deliveries out'!$H:$H,">="&$B$22,'Deliveries out'!$H:$H,"<="&$C$22,'Deliveries out'!$F:$F,$B33,'Deliveries out'!$E:$E,$C33) | E33: =COUNTIFS('Deliveries out'!$H:$H,">="&$B$22,'Deliveries out'!$H:$H,"<="&$C$22,'Deliveries out'!$F:$F,$B33,'Deliveries out'!$E:$E,$C33,'Deliveries out'!$K:$K,"Late")+COUNTIFS('Deliveries out'!$H:$H,">="&$B$22,'Deliveries out'!$H:$H,"<="&$C$22,'Deliveries out'!$F:$F,$B33,'Deliveries out'!$E:$E,$C33,'Deliveries out'!$K:$K,"Very late")+COUNTIFS('Deliveries out'!$H:$H,">="&$B$22,'Deliveries out'!$H:$H,"<="&$C$22,'Deliveries out'!$F:$F,$B33,'Deliveries out'!$E:$E,$C33,'Deliveries out'!$K:$K,"Overdue") | F33: =IF(D33=0,"",E33/D33)
A34: Own trucks · Ipswich | B34: Own trucks | C34: Ipswich | D34: =COUNTIFS('Deliveries out'!$H:$H,">="&$B$22,'Deliveries out'!$H:$H,"<="&$C$22,'Deliveries out'!$F:$F,$B34,'Deliveries out'!$E:$E,$C34) | E34: =COUNTIFS('Deliveries out'!$H:$H,">="&$B$22,'Deliveries out'!$H:$H,"<="&$C$22,'Deliveries out'!$F:$F,$B34,'Deliveries out'!$E:$E,$C34,'Deliveries out'!$K:$K,"Late")+COUNTIFS('Deliveries out'!$H:$H,">="&$B$22,'Deliveries out'!$H:$H,"<="&$C$22,'Deliveries out'!$F:$F,$B34,'Deliveries out'!$E:$E,$C34,'Deliveries out'!$K:$K,"Very late")+COUNTIFS('Deliveries out'!$H:$H,">="&$B$22,'Deliveries out'!$H:$H,"<="&$C$22,'Deliveries out'!$F:$F,$B34,'Deliveries out'!$E:$E,$C34,'Deliveries out'!$K:$K,"Overdue") | F34: =IF(D34=0,"",E34/D34)
A35: Same-day courier · Inner Brisbane | B35: Same-day courier | C35: Inner Brisbane | D35: =COUNTIFS('Deliveries out'!$H:$H,">="&$B$22,'Deliveries out'!$H:$H,"<="&$C$22,'Deliveries out'!$F:$F,$B35,'Deliveries out'!$E:$E,$C35) | E35: =COUNTIFS('Deliveries out'!$H:$H,">="&$B$22,'Deliveries out'!$H:$H,"<="&$C$22,'Deliveries out'!$F:$F,$B35,'Deliveries out'!$E:$E,$C35,'Deliveries out'!$K:$K,"Late")+COUNTIFS('Deliveries out'!$H:$H,">="&$B$22,'Deliveries out'!$H:$H,"<="&$C$22,'Deliveries out'!$F:$F,$B35,'Deliveries out'!$E:$E,$C35,'Deliveries out'!$K:$K,"Very late")+COUNTIFS('Deliveries out'!$H:$H,">="&$B$22,'Deliveries out'!$H:$H,"<="&$C$22,'Deliveries out'!$F:$F,$B35,'Deliveries out'!$E:$E,$C35,'Deliveries out'!$K:$K,"Overdue") | F35: =IF(D35=0,"",E35/D35)
A38: Late by supplier, last 30 days
A39: From | B39: 46272 | C39: 46301
A40: Supplier | B40: Supplier ID | D40: Due in period | E40: Late, very late or overdue | F40: % late
A41: Supplier A | B41: SUP2078 | D41: =COUNTIFS('Deliveries in'!$G:$G,">="&$B$39,'Deliveries in'!$G:$G,"<="&$C$39,'Deliveries in'!$C:$C,$B41) | E41: =COUNTIFS('Deliveries in'!$G:$G,">="&$B$39,'Deliveries in'!$G:$G,"<="&$C$39,'Deliveries in'!$C:$C,$B41,'Deliveries in'!$I:$I,"Late")+COUNTIFS('Deliveries in'!$G:$G,">="&$B$39,'Deliveries in'!$G:$G,"<="&$C$39,'Deliveries in'!$C:$C,$B41,'Deliveries in'!$I:$I,"Very late")+COUNTIFS('Deliveries in'!$G:$G,">="&$B$39,'Deliveries in'!$G:$G,"<="&$C$39,'Deliveries in'!$C:$C,$B41,'Deliveries in'!$I:$I,"Overdue") | F41: =IF(D41=0,"",E41/D41)
A42: Supplier C | B42: SUP2151 | D42: =COUNTIFS('Deliveries in'!$G:$G,">="&$B$39,'Deliveries in'!$G:$G,"<="&$C$39,'Deliveries in'!$C:$C,$B42) | E42: =COUNTIFS('Deliveries in'!$G:$G,">="&$B$39,'Deliveries in'!$G:$G,"<="&$C$39,'Deliveries in'!$C:$C,$B42,'Deliveries in'!$I:$I,"Late")+COUNTIFS('Deliveries in'!$G:$G,">="&$B$39,'Deliveries in'!$G:$G,"<="&$C$39,'Deliveries in'!$C:$C,$B42,'Deliveries in'!$I:$I,"Very late")+COUNTIFS('Deliveries in'!$G:$G,">="&$B$39,'Deliveries in'!$G:$G,"<="&$C$39,'Deliveries in'!$C:$C,$B42,'Deliveries in'!$I:$I,"Overdue") | F42: =IF(D42=0,"",E42/D42)
A43: Supplier D (imports) | B43: SUP2189 | D43: =COUNTIFS('Deliveries in'!$G:$G,">="&$B$39,'Deliveries in'!$G:$G,"<="&$C$39,'Deliveries in'!$C:$C,$B43) | E43: =COUNTIFS('Deliveries in'!$G:$G,">="&$B$39,'Deliveries in'!$G:$G,"<="&$C$39,'Deliveries in'!$C:$C,$B43,'Deliveries in'!$I:$I,"Late")+COUNTIFS('Deliveries in'!$G:$G,">="&$B$39,'Deliveries in'!$G:$G,"<="&$C$39,'Deliveries in'!$C:$C,$B43,'Deliveries in'!$I:$I,"Very late")+COUNTIFS('Deliveries in'!$G:$G,">="&$B$39,'Deliveries in'!$G:$G,"<="&$C$39,'Deliveries in'!$C:$C,$B43,'Deliveries in'!$I:$I,"Overdue") | F43: =IF(D43=0,"",E43/D43)
A44: Supplier K | B44: SUP2461 | D44: =COUNTIFS('Deliveries in'!$G:$G,">="&$B$39,'Deliveries in'!$G:$G,"<="&$C$39,'Deliveries in'!$C:$C,$B44) | E44: =COUNTIFS('Deliveries in'!$G:$G,">="&$B$39,'Deliveries in'!$G:$G,"<="&$C$39,'Deliveries in'!$C:$C,$B44,'Deliveries in'!$I:$I,"Late")+COUNTIFS('Deliveries in'!$G:$G,">="&$B$39,'Deliveries in'!$G:$G,"<="&$C$39,'Deliveries in'!$C:$C,$B44,'Deliveries in'!$I:$I,"Very late")+COUNTIFS('Deliveries in'!$G:$G,">="&$B$39,'Deliveries in'!$G:$G,"<="&$C$39,'Deliveries in'!$C:$C,$B44,'Deliveries in'!$I:$I,"Overdue") | F44: =IF(D44=0,"",E44/D44)
A45: Supplier E | B45: SUP2208 | D45: =COUNTIFS('Deliveries in'!$G:$G,">="&$B$39,'Deliveries in'!$G:$G,"<="&$C$39,'Deliveries in'!$C:$C,$B45) | E45: =COUNTIFS('Deliveries in'!$G:$G,">="&$B$39,'Deliveries in'!$G:$G,"<="&$C$39,'Deliveries in'!$C:$C,$B45,'Deliveries in'!$I:$I,"Late")+COUNTIFS('Deliveries in'!$G:$G,">="&$B$39,'Deliveries in'!$G:$G,"<="&$C$39,'Deliveries in'!$C:$C,$B45,'Deliveries in'!$I:$I,"Very late")+COUNTIFS('Deliveries in'!$G:$G,">="&$B$39,'Deliveries in'!$G:$G,"<="&$C$39,'Deliveries in'!$C:$C,$B45,'Deliveries in'!$I:$I,"Overdue") | F45: =IF(D45=0,"",E45/D45)
A46: Supplier G | B46: SUP2304 | D46: =COUNTIFS('Deliveries in'!$G:$G,">="&$B$39,'Deliveries in'!$G:$G,"<="&$C$39,'Deliveries in'!$C:$C,$B46) | E46: =COUNTIFS('Deliveries in'!$G:$G,">="&$B$39,'Deliveries in'!$G:$G,"<="&$C$39,'Deliveries in'!$C:$C,$B46,'Deliveries in'!$I:$I,"Late")+COUNTIFS('Deliveries in'!$G:$G,">="&$B$39,'Deliveries in'!$G:$G,"<="&$C$39,'Deliveries in'!$C:$C,$B46,'Deliveries in'!$I:$I,"Very late")+COUNTIFS('Deliveries in'!$G:$G,">="&$B$39,'Deliveries in'!$G:$G,"<="&$C$39,'Deliveries in'!$C:$C,$B46,'Deliveries in'!$I:$I,"Overdue") | F46: =IF(D46=0,"",E46/D46)
A47: Supplier B | B47: SUP2109 | D47: =COUNTIFS('Deliveries in'!$G:$G,">="&$B$39,'Deliveries in'!$G:$G,"<="&$C$39,'Deliveries in'!$C:$C,$B47) | E47: =COUNTIFS('Deliveries in'!$G:$G,">="&$B$39,'Deliveries in'!$G:$G,"<="&$C$39,'Deliveries in'!$C:$C,$B47,'Deliveries in'!$I:$I,"Late")+COUNTIFS('Deliveries in'!$G:$G,">="&$B$39,'Deliveries in'!$G:$G,"<="&$C$39,'Deliveries in'!$C:$C,$B47,'Deliveries in'!$I:$I,"Very late")+COUNTIFS('Deliveries in'!$G:$G,">="&$B$39,'Deliveries in'!$G:$G,"<="&$C$39,'Deliveries in'!$C:$C,$B47,'Deliveries in'!$I:$I,"Overdue") | F47: =IF(D47=0,"",E47/D47)
...

Sheet Customers
A1: Customers
A2: Sample Distribution · Wacol DC · SAMPLE DATA (invented) · The Fourth Sheet · Made with Python (openpyxl)
A3: Data status (data retrieved 2pm, Tue 6 Oct 2026): today's deliveries are incomplete; 1–5 October is provisional (until October is locked); September and earlier are locked. Generated 22 Oct 2026, 7:51pm.
A5: Customer ID | B5: Customer | C5: Suburb | D5: Region | E5: Latitude | F5: Longitude | G5: Usual carrier | H5: Deliveries a week
A6: C11107 | B6: Bulimba Hardware | C6: Bulimba | D6: Brisbane East | E6: -27.4558 | F6: 153.064 | G6: Own trucks | H6: 5
A7: C11143 | B7: Cannon Hill Cafe supplies | C7: Cannon Hill | D7: Brisbane East | E7: -27.4723 | F7: 153.0841 | G7: Own trucks | H7: 3
A8: C11314 | B8: Capalaba Pharmacy | C8: Capalaba | D8: Brisbane East | E8: -27.5467 | F8: 153.1907 | G8: Own trucks | H8: 5
A9: C11264 | B9: Carindale Auto parts | C9: Carindale | D9: Brisbane East | E9: -27.5069 | F9: 153.0995 | G9: Own trucks | H9: 5
A10: C10915 | B10: Eagle Farm Trade centre | C10: Eagle Farm | D10: Brisbane East | E10: -27.4348 | F10: 153.0912 | G10: Own trucks | H10: 3
A11: C10982 | B11: Hamilton Medical clinic | C11: Hamilton | D11: Brisbane East | E11: -27.4402 | F11: 153.0679 | G11: Own trucks | H11: 5
A12: C11186 | B12: Murarrie Building supplies | C12: Murarrie | D12: Brisbane East | E12: -27.4562 | F12: 153.1 | G12: Own trucks | H12: 3
A13: C11049 | B13: Pinkenba Garden centre | C13: Pinkenba | D13: Brisbane East | E13: -27.4236 | F13: 153.123 | G13: Own trucks | H13: 2
A14: C11247 | B14: Wynnum Pet supplies | C14: Wynnum | D14: Brisbane East | E14: -27.4439 | F14: 153.1743 | G14: Own trucks | H14: 4
A15: C10689 | B15: Aspley Auto parts | C15: Aspley | D15: Brisbane North | E15: -27.3605 | F15: 153.0159 | G15: Own trucks | H15: 2
A16: C10847 | B16: Banyo Grocer | C16: Banyo | D16: Brisbane North | E16: -27.3783 | F16: 153.0788 | G16: Own trucks | H16: 4
A17: C10684 | B17: Chermside Pet supplies | C17: Chermside | D17: Brisbane North | E17: -27.3799 | F17: 153.0366 | G17: Own trucks | H17: 2
... A70: C12639 | B70: Toowoomba Medical clinic 2 | C70: Toowoomba | D70: Toowoomba | E70: -27.5595 | F70: 151.9555 | G70: Carrier B | H70: 5

Sheet Suppliers
A1: Suppliers
A2: Sample Distribution · Wacol DC · SAMPLE DATA (invented) · The Fourth Sheet · Made with Python (openpyxl)
A3: Data status (data retrieved 2pm, Tue 6 Oct 2026): today's deliveries are incomplete; 1–5 October is provisional (until October is locked); September and earlier are locked. Generated 22 Oct 2026, 7:51pm.
A5: Supplier ID | B5: Supplier | C5: Place | D5: State | E5: Latitude | F5: Longitude | G5: Transit (working days) | H5: Usual carrier
A6: SUP2078 | B6: Supplier A | C6: Wetherill Park | D6: NSW | E6: -33.85 | F6: 150.9 | G6: 2 | H6: Line-haul (road)
A7: SUP2109 | B7: Supplier B | C7: Dandenong South | D7: VIC | E7: -38.02 | F7: 145.21 | G7: 3 | H7: Line-haul (road)
A8: SUP2151 | B8: Supplier C | C8: Laverton North | D8: VIC | E8: -37.83 | F8: 144.79 | G8: 3 | H8: Line-haul (road)
A9: SUP2189 | B9: Supplier D (imports) | C9: Port of Brisbane | D9: QLD | E9: -27.38 | F9: 153.17 | G9: 1 | H9: Container cartage
A10: SUP2208 | B10: Supplier E | C10: Yatala | D10: QLD | E10: -27.75 | F10: 153.22 | G10: 1 | H10: Supplier's own truck
A11: SUP2219 | B11: Supplier F | C11: Narangba | D11: QLD | E11: -27.2 | F11: 152.96 | G11: 1 | H11: Supplier's own truck
A12: SUP2304 | B12: Supplier G | C12: Toowoomba | D12: QLD | E12: -27.56 | F12: 151.95 | G12: 1 | H12: Supplier's own truck
A13: SUP2336 | B13: Supplier H | C13: Wingfield | D13: SA | E13: -34.85 | F13: 138.57 | G13: 4 | H13: Line-haul (road)
A14: SUP2422 | B14: Supplier I | C14: Kewdale | D14: WA | E14: -31.98 | F14: 115.95 | G14: 6 | H14: Line-haul (rail)
A15: SUP2438 | B15: Supplier J | C15: Beresfield | D15: NSW | E15: -32.8 | F15: 151.65 | G15: 2 | H15: Line-haul (road)
A16: SUP2461 | B16: Supplier K | C16: Townsville | D16: QLD | E16: -19.26 | F16: 146.82 | G16: 3 | H16: Line-haul (road)
A17: SUP2480 | B17: Supplier L | C17: Rocklea | D17: QLD | E17: -27.54 | F17: 152.99 | G17: 1 | H17: Supplier's own truck
... A19: SUP2542 | B19: Supplier N | C19: Bundamba | D19: QLD | E19: -27.61 | F19: 152.8 | G19: 1 | H19: Supplier's own truck

Sheet Deliveries out
A1: Every delivery out, 3 Aug to 6 Oct 2026
A2: Sample Distribution · Wacol DC · SAMPLE DATA (invented) · The Fourth Sheet · Made with Python (openpyxl)
A3: Data status (data retrieved 2pm, Tue 6 Oct 2026): today's deliveries are incomplete; 1–5 October is provisional (until October is locked); September and earlier are locked. Generated 22 Oct 2026, 7:51pm.
A5: Delivery | B5: Order | C5: Customer ID | D5: Customer | E5: Region | F5: Carrier | G5: Order date | H5: Promised | I5: Delivered | J5: Time | K5: Status | L5: Working days late | M5: Late reason | N5: Cartons | O5: Order value | P5: In full | Q5: Completed
A6: DN318207 | B6: SO61874 | C6: C10268 | D6: =INDEX(Customers!$B:$B,MATCH(C6,Customers!$A:$A,0)) | E6: =INDEX(Customers!$D:$D,MATCH(C6,Customers!$A:$A,0)) | F6: Own trucks | G6: 46234 | H6: 46237 | I6: 46237 | J6: 08:10 | K6: On time | L6: 0 | N6: 40 | O6: 5360 | P6: 1 | Q6: =IF(OR(K6="On time",K6="Late",K6="Very late"),1,0)
A7: DN318208 | B7: SO61875 | C7: C10322 | D7: =INDEX(Customers!$B:$B,MATCH(C7,Customers!$A:$A,0)) | E7: =INDEX(Customers!$D:$D,MATCH(C7,Customers!$A:$A,0)) | F7: Own trucks | G7: 46234 | H7: 46237 | I7: 46237 | J7: 14:40 | K7: On time | L7: 0 | N7: 30 | O7: 2550 | P7: 0 | Q7: =IF(OR(K7="On time",K7="Late",K7="Very late"),1,0)
A8: DN318209 | B8: SO61876 | C8: C10343 | D8: =INDEX(Customers!$B:$B,MATCH(C8,Customers!$A:$A,0)) | E8: =INDEX(Customers!$D:$D,MATCH(C8,Customers!$A:$A,0)) | F8: Own trucks | G8: 46234 | H8: 46237 | I8: 46237 | J8: 07:50 | K8: On time | L8: 0 | N8: 33 | O8: 3135 | P8: 1 | Q8: =IF(OR(K8="On time",K8="Late",K8="Very late"),1,0)
A9: DN318210 | B9: SO61877 | C9: C10413 | D9: =INDEX(Customers!$B:$B,MATCH(C9,Customers!$A:$A,0)) | E9: =INDEX(Customers!$D:$D,MATCH(C9,Customers!$A:$A,0)) | F9: Own trucks | G9: 46234 | H9: 46237 | I9: 46237 | J9: 13:50 | K9: On time | L9: 0 | N9: 34 | O9: 4624 | P9: 1 | Q9: =IF(OR(K9="On time",K9="Late",K9="Very late"),1,0)
A10: DN318211 | B10: SO61878 | C10: C10446 | D10: =INDEX(Customers!$B:$B,MATCH(C10,Customers!$A:$A,0)) | E10: =INDEX(Customers!$D:$D,MATCH(C10,Customers!$A:$A,0)) | F10: Own trucks | G10: 46234 | H10: 46237 | I10: 46237 | J10: 14:10 | K10: On time | L10: 0 | N10: 38 | O10: 3572 | P10: 0 | Q10: =IF(OR(K10="On time",K10="Late",K10="Very late"),1,0)
A11: DN318212 | B11: SO61879 | C11: C10522 | D11: =INDEX(Customers!$B:$B,MATCH(C11,Customers!$A:$A,0)) | E11: =INDEX(Customers!$D:$D,MATCH(C11,Customers!$A:$A,0)) | F11: Own trucks | G11: 46234 | H11: 46237 | I11: 46237 | J11: 16:40 | K11: On time | L11: 0 | N11: 33 | O11: 2277 | P11: 1 | Q11: =IF(OR(K11="On time",K11="Late",K11="Very late"),1,0)
A12: DN318213 | B12: SO61880 | C12: C10536 | D12: =INDEX(Customers!$B:$B,MATCH(C12,Customers!$A:$A,0)) | E12: =INDEX(Customers!$D:$D,MATCH(C12,Customers!$A:$A,0)) | F12: Own trucks | G12: 46234 | H12: 46237 | I12: 46237 | J12: 14:30 | K12: On time | L12: 0 | N12: 35 | O12: 3080 | P12: 1 | Q12: =IF(OR(K12="On time",K12="Late",K12="Very late"),1,0)
A13: DN318214 | B13: SO61881 | C13: C10622 | D13: =INDEX(Customers!$B:$B,MATCH(C13,Customers!$A:$A,0)) | E13: =INDEX(Customers!$D:$D,MATCH(C13,Customers!$A:$A,0)) | F13: Own trucks | G13: 46234 | H13: 46237 | I13: 46237 | J13: 16:10 | K13: On time | L13: 0 | N13: 10 | O13: 610 | P13: 1 | Q13: =IF(OR(K13="On time",K13="Late",K13="Very late"),1,0)
A14: DN318215 | B14: SO61882 | C14: C10676 | D14: =INDEX(Customers!$B:$B,MATCH(C14,Customers!$A:$A,0)) | E14: =INDEX(Customers!$D:$D,MATCH(C14,Customers!$A:$A,0)) | F14: Own trucks | G14: 46234 | H14: 46237 | I14: 46237 | J14: 13:30 | K14: On time | L14: 0 | N14: 11 | O14: 1276 | P14: 1 | Q14: =IF(OR(K14="On time",K14="Late",K14="Very late"),1,0)
A15: DN318216 | B15: SO61883 | C15: C10689 | D15: =INDEX(Customers!$B:$B,MATCH(C15,Customers!$A:$A,0)) | E15: =INDEX(Customers!$D:$D,MATCH(C15,Customers!$A:$A,0)) | F15: Own trucks | G15: 46234 | H15: 46237 | I15: 46237 | J15: 14:50 | K15: On time | L15: 0 | N15: 36 | O15: 3132 | P15: 1 | Q15: =IF(OR(K15="On time",K15="Late",K15="Very late"),1,0)
A16: DN318217 | B16: SO61884 | C16: C10796 | D16: =INDEX(Customers!$B:$B,MATCH(C16,Customers!$A:$A,0)) | E16: =INDEX(Customers!$D:$D,MATCH(C16,Customers!$A:$A,0)) | F16: Own trucks | G16: 46234 | H16: 46237 | I16: 46237 | J16: 15:50 | K16: On time | L16: 0 | N16: 32 | O16: 3392 | P16: 1 | Q16: =IF(OR(K16="On time",K16="Late",K16="Very late"),1,0)
A17: DN318218 | B17: SO61885 | C17: C10847 | D17: =INDEX(Customers!$B:$B,MATCH(C17,Customers!$A:$A,0)) | E17: =INDEX(Customers!$D:$D,MATCH(C17,Customers!$A:$A,0)) | F17: Own trucks | G17: 46234 | H17: 46237 | I17: 46237 | J17: 07:10 | K17: On time | L17: 0 | N17: 40 | O17: 4520 | P17: 1 | Q17: =IF(OR(K17="On time",K17="Late",K17="Very late"),1,0)
... A35: DN318236 | B35: SO61905 | C35: C12365 | D35: =INDEX(Customers!$B:$B,MATCH(C35,Customers!$A:$A,0)) | E35: =INDEX(Customers!$D:$D,MATCH(C35,Customers!$A:$A,0)) | F35: Carrier B | G35: 46234 | H35: 46237 | I35: 46237 | J35: 14:50 | K35: On time | L35: 0 | N35: 23 | O35: 2461 | P35: 1 | Q35: =IF(OR(K35="On time",K35="Late",K35="Very late"),1,0)
A36: DN318237 | B36: SO61906 | C36: C12393 | D36: =INDEX(Customers!$B:$B,MATCH(C36,Customers!$A:$A,0)) | E36: =INDEX(Customers!$D:$D,MATCH(C36,Customers!$A:$A,0)) | F36: Carrier A | G36: 46234 | H36: 46237 | I36: 46239 | J36: 16:40 | K36: Very late | L36: 2 | M36: Carrier delay | N36: 15 | O36: 1035 | P36: 1 | Q36: =IF(OR(K36="On time",K36="Late",K36="Very late"),1,0)
A37: DN318238 | B37: SO61907 | C37: C12420 | D37: =INDEX(Customers!$B:$B,MATCH(C37,Customers!$A:$A,0)) | E37: =INDEX(Customers!$D:$D,MATCH(C37,Customers!$A:$A,0)) | F37: Carrier A | G37: 46234 | H37: 46237 | I37: 46237 | J37: 10:40 | K37: On time | L37: 0 | N37: 20 | O37: 2540 | P37: 1 | Q37: =IF(OR(K37="On time",K37="Late",K37="Very late"),1,0)
A38: DN318239 | B38: SO61909 | C38: C12490 | D38: =INDEX(Customers!$B:$B,MATCH(C38,Customers!$A:$A,0)) | E38: =INDEX(Customers!$D:$D,MATCH(C38,Customers!$A:$A,0)) | F38: Carrier A | G38: 46234 | H38: 46237 | I38: 46238 | J38: 07:20 | K38: Late | L38: 1 | M38: Carrier delay | N38: 13 | O38: 1781 | P38: 1 | Q38: =IF(OR(K38="On time",K38="Late",K38="Very late"),1,0)
A39: DN318240 | B39: SO61910 | C39: C12543 | D39: =INDEX(Customers!$B:$B,MATCH(C39,Customers!$A:$A,0)) | E39: =INDEX(Customers!$D:$D,MATCH(C39,Customers!$A:$A,0)) | F39: Carrier B | G39: 46233 | H39: 46237 | I39: 46237 | J39: 11:20 | K39: On time | L39: 0 | N39: 12 | O39: 1056 | P39: 1 | Q39: =IF(OR(K39="On time",K39="Late",K39="Very late"),1,0)
A40: DN318241 | B40: SO61911 | C40: C12557 | D40: =INDEX(Customers!$B:$B,MATCH(C40,Customers!$A:$A,0)) | E40: =INDEX(Customers!$D:$D,MATCH(C40,Customers!$A:$A,0)) | F40: Carrier B | G40: 46233 | H40: 46237 | I40: 46237 | J40: 11:30 | K40: On time | L40: 0 | N40: 2 | O40: 124 | P40: 1 | Q40: =IF(OR(K40="On time",K40="Late",K40="Very late"),1,0)
A41: DN318242 | B41: SO61912 | C41: C12617 | D41: =INDEX(Customers!$B:$B,MATCH(C41,Customers!$A:$A,0)) | E41: =INDEX(Customers!$D:$D,MATCH(C41,Customers!$A:$A,0)) | F41: Carrier B | G41: 46233 | H41: 46237 | I41: 46237 | J41: 15:40 | K41: On time | L41: 0 | N41: 24 | O41: 2280 | P41: 1 | Q41: =IF(OR(K41="On time",K41="Late",K41="Very late"),1,0)
A42: DN318243 | B42: SO61914 | C42: C12639 | D42: =INDEX(Customers!$B:$B,MATCH(C42,Customers!$A:$A,0)) | E42: =INDEX(Customers!$D:$D,MATCH(C42,Customers!$A:$A,0)) | F42: Carrier B | G42: 46233 | H42: 46237 | I42: 46237 | J42: 13:20 | K42: On time | L42: 0 | N42: 40 | O42: 3280 | P42: 1 | Q42: =IF(OR(K42="On time",K42="Late",K42="Very late"),1,0)
A43: DN318244 | B43: SO61915 | C43: C12675 | D43: =INDEX(Customers!$B:$B,MATCH(C43,Customers!$A:$A,0)) | E43: =INDEX(Customers!$D:$D,MATCH(C43,Customers!$A:$A,0)) | F43: Carrier B | G43: 46233 | H43: 46237 | I43: 46237 | J43: 08:50 | K43: On time | L43: 0 | N43: 25 | O43: 2975 | P43: 1 | Q43: =IF(OR(K43="On time",K43="Late",K43="Very late"),1,0)
A44: DN318245 | B44: SO61917 | C44: C10322 | D44: =INDEX(Customers!$B:$B,MATCH(C44,Customers!$A:$A,0)) | E44: =INDEX(Customers!$D:$D,MATCH(C44,Customers!$A:$A,0)) | F44: Own trucks | G44: 46237 | H44: 46238 | I44: 46238 | J44: 13:00 | K44: On time | L44: 0 | N44: 20 | O44: 1940 | P44: 1 | Q44: =IF(OR(K44="On time",K44="Late",K44="Very late"),1,0)
A45: DN318246 | B45: SO61918 | C45: C10343 | D45: =INDEX(Customers!$B:$B,MATCH(C45,Customers!$A:$A,0)) | E45: =INDEX(Customers!$D:$D,MATCH(C45,Customers!$A:$A,0)) | F45: Own trucks | G45: 46237 | H45: 46238 | I45: 46238 | J45: 13:20 | K45: On time | L45: 0 | N45: 39 | O45: 2223 | P45: 1 | Q45: =IF(OR(K45="On time",K45="Late",K45="Very late"),1,0)
A46: DN318247 | B46: SO61919 | C46: C10413 | D46: =INDEX(Customers!$B:$B,MATCH(C46,Customers!$A:$A,0)) | E46: =INDEX(Customers!$D:$D,MATCH(C46,Customers!$A:$A,0)) | F46: Own trucks | G46: 46237 | H46: 46238 | I46: 46238 | J46: 08:10 | K46: On time | L46: 0 | N46: 9 | O46: 630 | P46: 1 | Q46: =IF(OR(K46="On time",K46="Late",K46="Very late"),1,0)
A47: DN318248 | B47: SO61921 | C47: C10446 | D47: =INDEX(Customers!$B:$B,MATCH(C47,Customers!$A:$A,0)) | E47: =INDEX(Customers!$D:$D,MATCH(C47,Customers!$A:$A,0)) | F47: Own trucks | G47: 46237 | H47: 46238 | I47: 46238 | J47: 11:00 | K47: On time | L47: 0 | N47: 29 | O47: 3741 | P47: 1 | Q47: =IF(OR(K47="On time",K47="Late",K47="Very late"),1,0)
A48: DN318249 | B48: SO61922 | C48: C10522 | D48: =INDEX(Customers!$B:$B,MATCH(C48,Customers!$A:$A,0)) | E48: =INDEX(Customers!$D:$D,MATCH(C48,Customers!$A:$A,0)) | F48: Own trucks | G48: 46237 | H48: 46238 | I48: 46238 | J48: 09:10 | K48: On time | L48: 0 | N48: 36 | O48: 2088 | P48: 1 | Q48: =IF(OR(K48="On time",K48="Late",K48="Very late"),1,0)
A49: DN318250 | B49: SO61923 | C49: C10536 | D49: =INDEX(Customers!$B:$B,MATCH(C49,Customers!$A:$A,0)) | E49: =INDEX(Customers!$D:$D,MATCH(C49,Customers!$A:$A,0)) | F49: Own trucks | G49: 46237 | H49: 46238 | I49: 46238 | J49: 13:20 | K49: On time | L49: 0 | N49: 11 | O49: 924 | P49: 0 | Q49: =IF(OR(K49="On time",K49="Late",K49="Very late"),1,0)
A50: DN318251 | B50: SO61924 | C50: C10589 | D50: =INDEX(Customers!$B:$B,MATCH(C50,Customers!$A:$A,0)) | E50: =INDEX(Customers!$D:$D,MATCH(C50,Customers!$A:$A,0)) | F50: Own trucks | G50: 46237 | H50: 46238 | I50: 46238 | J50: 12:10 | K50: On time | L50: 0 | N50: 39 | O50: 2574 | P50: 1 | Q50: =IF(OR(K50="On time",K50="Late",K50="Very late"),1,0)
... A82: DN318285 | B82: SO61958 | C82: C12543 | D82: =INDEX(Customers!$B:$B,MATCH(C82,Customers!$A:$A,0)) | E82: =INDEX(Customers!$D:$D,MATCH(C82,Customers!$A:$A,0)) | F82: Carrier B | G82: 46234 | H82: 46238 | I82: 46238 | J82: 12:20 | K82: On time | L82: 0 | N82: 40 | O82: 4640 | P82: 1 | Q82: =IF(OR(K82="On time",K82="Late",K82="Very late"),1,0)
A83: DN318287 | B83: SO61959 | C83: C12617 | D83: =INDEX(Customers!$B:$B,MATCH(C83,Customers!$A:$A,0)) | E83: =INDEX(Customers!$D:$D,MATCH(C83,Customers!$A:$A,0)) | F83: Carrier B | G83: 46234 | H83: 46238 | I83: 46239 | J83: 12:20 | K83: Late | L83: 1 | M83: Carrier delay | N83: 31 | O83: 2480 | P83: 1 | Q83: =IF(OR(K83="On time",K83="Late",K83="Very late"),1,0)
A84: DN318288 | B84: SO61960 | C84: C12639 | D84: =INDEX(Customers!$B:$B,MATCH(C84,Customers!$A:$A,0)) | E84: =INDEX(Customers!$D:$D,MATCH(C84,Customers!$A:$A,0)) | F84: Carrier B | G84: 46234 | H84: 46238 | I84: 46238 | J84: 16:00 | K84: On time | L84: 0 | N84: 28 | O84: 1764 | P84: 1 | Q84: =IF(OR(K84="On time",K84="Late",K84="Very late"),1,0)
A85: DN318289 | B85: SO61961 | C85: C12675 | D85: =INDEX(Customers!$B:$B,MATCH(C85,Customers!$A:$A,0)) | E85: =INDEX(Customers!$D:$D,MATCH(C85,Customers!$A:$A,0)) | F85: Carrier B | G85: 46234 | H85: 46238 | I85: 46238 | J85: 15:20 | K85: On time | L85: 0 | N85: 32 | O85: 4256 | P85: 1 | Q85: =IF(OR(K85="On time",K85="Late",K85="Very late"),1,0)
A86: DN318290 | B86: SO61962 | C86: C10322 | D86: =INDEX(Customers!$B:$B,MATCH(C86,Customers!$A:$A,0)) | E86: =INDEX(Customers!$D:$D,MATCH(C86,Customers!$A:$A,0)) | F86: Own trucks | G86: 46238 | H86: 46239 | I86: 46239 | J86: 12:20 | K86: On time | L86: 0 | N86: 13 | O86: 832 | P86: 1 | Q86: =IF(OR(K86="On time",K86="Late",K86="Very late"),1,0)
A87: DN318291 | B87: SO61963 | C87: C10343 | D87: =INDEX(Customers!$B:$B,MATCH(C87,Customers!$A:$A,0)) | E87: =INDEX(Customers!$D:$D,MATCH(C87,Customers!$A:$A,0)) | F87: Own trucks | G87: 46238 | H87: 46239 | I87: 46239 | J87: 15:40 | K87: On time | L87: 0 | N87: 26 | O87: 3510 | P87: 1 | Q87: =IF(OR(K87="On time",K87="Late",K87="Very late"),1,0)
A88: DN318292 | B88: SO61964 | C88: C10446 | D88: =INDEX(Customers!$B:$B,MATCH(C88,Customers!$A:$A,0)) | E88: =INDEX(Customers!$D:$D,MATCH(C88,Customers!$A:$A,0)) | F88: Own trucks | G88: 46238 | H88: 46239 | I88: 46239 | J88: 15:40 | K88: On time | L88: 0 | N88: 10 | O88: 1200 | P88: 1 | Q88: =IF(OR(K88="On time",K88="Late",K88="Very late"),1,0)
A89: DN318293 | B89: SO61965 | C89: C10522 | D89: =INDEX(Customers!$B:$B,MATCH(C89,Customers!$A:$A,0)) | E89: =INDEX(Customers!$D:$D,MATCH(C89,Customers!$A:$A,0)) | F89: Own trucks | G89: 46238 | H89: 46239 | I89: 46239 | J89: 12:20 | K89: On time | L89: 0 | N89: 27 | O89: 3321 | P89: 1 | Q89: =IF(OR(K89="On time",K89="Late",K89="Very late"),1,0)
...

Sheet Deliveries in
A1: Every purchase-order delivery in, due 3 Aug to 9 Oct 2026
A2: Sample Distribution · Wacol DC · SAMPLE DATA (invented) · The Fourth Sheet · Made with Python (openpyxl)
A3: Data status (data retrieved 2pm, Tue 6 Oct 2026): today's deliveries are incomplete; 1–5 October is provisional (until October is locked); September and earlier are locked. Generated 22 Oct 2026, 7:51pm.
A5: Receipt | B5: PO | C5: Supplier ID | D5: Supplier | E5: Carrier | F5: PO date | G5: Due | H5: Arrived | I5: Status | J5: Working days late | K5: Late reason | L5: Lines | M5: Lines short | N5: PO value | O5: Completed | P5: In full
A6: GRN52115 | B6: PO18344 | C6: SUP2078 | D6: =INDEX(Suppliers!$B:$B,MATCH(C6,Suppliers!$A:$A,0)) | E6: Line-haul (road) | F6: 46225 | G6: 46237 | H6: 46237 | I6: On time | J6: 0 | L6: 30 | M6: 0 | N6: 24420 | O6: =IF(OR(I6="On time",I6="Late",I6="Very late"),1,0) | P6: =IF(AND(O6=1,M6=0),1,0)
A7: GRN52116 | B7: PO18345 | C7: SUP2208 | D7: =INDEX(Suppliers!$B:$B,MATCH(C7,Suppliers!$A:$A,0)) | E7: Supplier's own truck | F7: 46231 | G7: 46237 | H7: 46237 | I7: On time | J7: 0 | L7: 23 | M7: 0 | N7: 16008 | O7: =IF(OR(I7="On time",I7="Late",I7="Very late"),1,0) | P7: =IF(AND(O7=1,M7=0),1,0)
A8: GRN52117 | B8: PO18347 | C8: SUP2304 | D8: =INDEX(Suppliers!$B:$B,MATCH(C8,Suppliers!$A:$A,0)) | E8: Supplier's own truck | F8: 46227 | G8: 46237 | H8: 46237 | I8: On time | J8: 0 | L8: 4 | M8: 0 | N8: 1368 | O8: =IF(OR(I8="On time",I8="Late",I8="Very late"),1,0) | P8: =IF(AND(O8=1,M8=0),1,0)
A9: GRN52118 | B9: PO18349 | C9: SUP2422 | D9: =INDEX(Suppliers!$B:$B,MATCH(C9,Suppliers!$A:$A,0)) | E9: Line-haul (rail) | F9: 46219 | G9: 46237 | H9: 46237 | I9: On time | J9: 0 | L9: 4 | M9: 0 | N9: 3512 | O9: =IF(OR(I9="On time",I9="Late",I9="Very late"),1,0) | P9: =IF(AND(O9=1,M9=0),1,0)
A10: GRN52119 | B10: PO18350 | C10: SUP2461 | D10: =INDEX(Suppliers!$B:$B,MATCH(C10,Suppliers!$A:$A,0)) | E10: Line-haul (road) | F10: 46227 | G10: 46237 | H10: 46237 | I10: On time | J10: 0 | L10: 16 | M10: 0 | N10: 10032 | O10: =IF(OR(I10="On time",I10="Late",I10="Very late"),1,0) | P10: =IF(AND(O10=1,M10=0),1,0)
A11: GRN52120 | B11: PO18351 | C11: SUP2506 | D11: =INDEX(Suppliers!$B:$B,MATCH(C11,Suppliers!$A:$A,0)) | E11: Air freight | F11: 46227 | G11: 46237 | H11: 46237 | I11: On time | J11: 0 | L11: 12 | M11: 0 | N11: 8844 | O11: =IF(OR(I11="On time",I11="Late",I11="Very late"),1,0) | P11: =IF(AND(O11=1,M11=0),1,0)
A12: GRN52121 | B12: PO18352 | C12: SUP2078 | D12: =INDEX(Suppliers!$B:$B,MATCH(C12,Suppliers!$A:$A,0)) | E12: Line-haul (road) | F12: 46231 | G12: 46238 | H12: 46238 | I12: On time | J12: 0 | L12: 7 | M12: 0 | N12: 3724 | O12: =IF(OR(I12="On time",I12="Late",I12="Very late"),1,0) | P12: =IF(AND(O12=1,M12=0),1,0)
A13: GRN52122 | B13: PO18354 | C13: SUP2151 | D13: =INDEX(Suppliers!$B:$B,MATCH(C13,Suppliers!$A:$A,0)) | E13: Line-haul (road) | F13: 46225 | G13: 46238 | H13: 46238 | I13: On time | J13: 0 | L13: 6 | M13: 0 | N13: 4284 | O13: =IF(OR(I13="On time",I13="Late",I13="Very late"),1,0) | P13: =IF(AND(O13=1,M13=0),1,0)
A14: GRN52123 | B14: PO18356 | C14: SUP2189 | D14: =INDEX(Suppliers!$B:$B,MATCH(C14,Suppliers!$A:$A,0)) | E14: Container cartage | F14: 46231 | G14: 46238 | H14: 46238 | I14: On time | J14: 0 | L14: 11 | M14: 0 | N14: 9581 | O14: =IF(OR(I14="On time",I14="Late",I14="Very late"),1,0) | P14: =IF(AND(O14=1,M14=0),1,0)
A15: GRN52124 | B15: PO18357 | C15: SUP2304 | D15: =INDEX(Suppliers!$B:$B,MATCH(C15,Suppliers!$A:$A,0)) | E15: Supplier's own truck | F15: 46227 | G15: 46238 | H15: 46239 | I15: Late | J15: 1 | K15: Line-haul delay | L15: 16 | M15: 0 | N15: 6304 | O15: =IF(OR(I15="On time",I15="Late",I15="Very late"),1,0) | P15: =IF(AND(O15=1,M15=0),1,0)
A16: GRN52125 | B16: PO18358 | C16: SUP2461 | D16: =INDEX(Suppliers!$B:$B,MATCH(C16,Suppliers!$A:$A,0)) | E16: Line-haul (road) | F16: 46226 | G16: 46238 | H16: 46238 | I16: On time | J16: 0 | L16: 15 | M16: 0 | N16: 9780 | O16: =IF(OR(I16="On time",I16="Late",I16="Very late"),1,0) | P16: =IF(AND(O16=1,M16=0),1,0)
A17: GRN52126 | B17: PO18359 | C17: SUP2078 | D17: =INDEX(Suppliers!$B:$B,MATCH(C17,Suppliers!$A:$A,0)) | E17: Line-haul (road) | F17: 46233 | G17: 46239 | H17: 46244 | I17: Very late | J17: 3 | K17: Line-haul delay | L17: 7 | M17: 0 | N17: 3738 | O17: =IF(OR(I17="On time",I17="Late",I17="Very late"),1,0) | P17: =IF(AND(O17=1,M17=0),1,0)
A18: GRN52127 | B18: PO18361 | C18: SUP2189 | D18: =INDEX(Suppliers!$B:$B,MATCH(C18,Suppliers!$A:$A,0)) | E18: Container cartage | F18: 46231 | G18: 46239 | H18: 46239 | I18: On time | J18: 0 | L18: 28 | M18: 0 | N18: 12292 | O18: =IF(OR(I18="On time",I18="Late",I18="Very late"),1,0) | P18: =IF(AND(O18=1,M18=0),1,0)
A19: GRN52128 | B19: PO18363 | C19: SUP2208 | D19: =INDEX(Suppliers!$B:$B,MATCH(C19,Suppliers!$A:$A,0)) | E19: Supplier's own truck | F19: 46231 | G19: 46239 | H19: 46240 | I19: Late | J19: 1 | K19: Supplier stock shortage | L19: 6 | M19: 0 | N19: 2832 | O19: =IF(OR(I19="On time",I19="Late",I19="Very late"),1,0) | P19: =IF(AND(O19=1,M19=0),1,0)
A20: GRN52129 | B20: PO18365 | C20: SUP2336 | D20: =INDEX(Suppliers!$B:$B,MATCH(C20,Suppliers!$A:$A,0)) | E20: Line-haul (road) | F20: 46230 | G20: 46239 | H20: 46239 | I20: On time | J20: 0 | L20: 11 | M20: 0 | N20: 7007 | O20: =IF(OR(I20="On time",I20="Late",I20="Very late"),1,0) | P20: =IF(AND(O20=1,M20=0),1,0)
A21: GRN52130 | B21: PO18367 | C21: SUP2506 | D21: =INDEX(Suppliers!$B:$B,MATCH(C21,Suppliers!$A:$A,0)) | E21: Air freight | F21: 46232 | G21: 46239 | H21: 46239 | I21: On time | J21: 0 | L21: 10 | M21: 0 | N21: 2000 | O21: =IF(OR(I21="On time",I21="Late",I21="Very late"),1,0) | P21: =IF(AND(O21=1,M21=0),1,0)
A22: GRN52131 | B22: PO18368 | C22: SUP2208 | D22: =INDEX(Suppliers!$B:$B,MATCH(C22,Suppliers!$A:$A,0)) | E22: Supplier's own truck | F22: 46237 | G22: 46240 | H22: 46240 | I22: On time | J22: 0 | L22: 6 | M22: 0 | N22: 4884 | O22: =IF(OR(I22="On time",I22="Late",I22="Very late"),1,0) | P22: =IF(AND(O22=1,M22=0),1,0)
A23: GRN52132 | B23: PO18369 | C23: SUP2304 | D23: =INDEX(Suppliers!$B:$B,MATCH(C23,Suppliers!$A:$A,0)) | E23: Supplier's own truck | F23: 46232 | G23: 46240 | H23: 46240 | I23: On time | J23: 0 | L23: 19 | M23: 0 | N23: 5092 | O23: =IF(OR(I23="On time",I23="Late",I23="Very late"),1,0) | P23: =IF(AND(O23=1,M23=0),1,0)
A24: GRN52133 | B24: PO18370 | C24: SUP2422 | D24: =INDEX(Suppliers!$B:$B,MATCH(C24,Suppliers!$A:$A,0)) | E24: Line-haul (rail) | F24: 46226 | G24: 46240 | H24: 46240 | I24: On time | J24: 0 | L24: 3 | M24: 0 | N24: 2274 | O24: =IF(OR(I24="On time",I24="Late",I24="Very late"),1,0) | P24: =IF(AND(O24=1,M24=0),1,0)
A25: GRN52134 | B25: PO18371 | C25: SUP2542 | D25: =INDEX(Suppliers!$B:$B,MATCH(C25,Suppliers!$A:$A,0)) | E25: Supplier's own truck | F25: 46232 | G25: 46240 | H25: 46240 | I25: On time | J25: 0 | L25: 12 | M25: 0 | N25: 2760 | O25: =IF(OR(I25="On time",I25="Late",I25="Very late"),1,0) | P25: =IF(AND(O25=1,M25=0),1,0)
A26: GRN52135 | B26: PO18372 | C26: SUP2189 | D26: =INDEX(Suppliers!$B:$B,MATCH(C26,Suppliers!$A:$A,0)) | E26: Container cartage | F26: 46234 | G26: 46241 | H26: 46241 | I26: On time | J26: 0 | L26: 23 | M26: 0 | N26: 19113 | O26: =IF(OR(I26="On time",I26="Late",I26="Very late"),1,0) | P26: =IF(AND(O26=1,M26=0),1,0)
A27: GRN52136 | B27: PO18373 | C27: SUP2219 | D27: =INDEX(Suppliers!$B:$B,MATCH(C27,Suppliers!$A:$A,0)) | E27: Supplier's own truck | F27: 46237 | G27: 46241 | H27: 46241 | I27: On time | J27: 0 | L27: 18 | M27: 0 | N27: 8244 | O27: =IF(OR(I27="On time",I27="Late",I27="Very late"),1,0) | P27: =IF(AND(O27=1,M27=0),1,0)
A28: GRN52137 | B28: PO18375 | C28: SUP2304 | D28: =INDEX(Suppliers!$B:$B,MATCH(C28,Suppliers!$A:$A,0)) | E28: Supplier's own truck | F28: 46238 | G28: 46241 | H28: 46241 | I28: On time | J28: 0 | L28: 3 | M28: 0 | N28: 1650 | O28: =IF(OR(I28="On time",I28="Late",I28="Very late"),1,0) | P28: =IF(AND(O28=1,M28=0),1,0)
A29: GRN52138 | B29: PO18377 | C29: SUP2480 | D29: =INDEX(Suppliers!$B:$B,MATCH(C29,Suppliers!$A:$A,0)) | E29: Supplier's own truck | F29: 46232 | G29: 46241 | H29: 46241 | I29: On time | J29: 0 | L29: 22 | M29: 0 | N29: 15774 | O29: =IF(OR(I29="On time",I29="Late",I29="Very late"),1,0) | P29: =IF(AND(O29=1,M29=0),1,0)
A30: GRN52139 | B30: PO18378 | C30: SUP2506 | D30: =INDEX(Suppliers!$B:$B,MATCH(C30,Suppliers!$A:$A,0)) | E30: Air freight | F30: 46234 | G30: 46241 | H30: 46241 | I30: On time | J30: 0 | L30: 29 | M30: 0 | N30: 18821 | O30: =IF(OR(I30="On time",I30="Late",I30="Very late"),1,0) | P30: =IF(AND(O30=1,M30=0),1,0)
A31: GRN52140 | B31: PO18379 | C31: SUP2542 | D31: =INDEX(Suppliers!$B:$B,MATCH(C31,Suppliers!$A:$A,0)) | E31: Supplier's own truck | F31: 46237 | G31: 46241 | H31: 46241 | I31: On time | J31: 0 | L31: 25 | M31: 0 | N31: 17675 | O31: =IF(OR(I31="On time",I31="Late",I31="Very late"),1,0) | P31: =IF(AND(O31=1,M31=0),1,0)
... A35: GRN52145 | B35: PO18384 | C35: SUP2208 | D35: =INDEX(Suppliers!$B:$B,MATCH(C35,Suppliers!$A:$A,0)) | E35: Supplier's own truck | F35: 46233 | G35: 46244 | H35: 46244 | I35: On time | J35: 0 | L35: 18 | M35: 0 | N35: 12042 | O35: =IF(OR(I35="On time",I35="Late",I35="Very late"),1,0) | P35: =IF(AND(O35=1,M35=0),1,0)
A36: GRN52146 | B36: PO18385 | C36: SUP2304 | D36: =INDEX(Suppliers!$B:$B,MATCH(C36,Suppliers!$A:$A,0)) | E36: Supplier's own truck | F36: 46234 | G36: 46244 | H36: 46245 | I36: Late | J36: 1 | K36: Booking slot missed | L36: 24 | M36: 0 | N36: 11472 | O36: =IF(OR(I36="On time",I36="Late",I36="Very late"),1,0) | P36: =IF(AND(O36=1,M36=0),1,0)
A37: GRN52147 | B37: PO18386 | C37: SUP2422 | D37: =INDEX(Suppliers!$B:$B,MATCH(C37,Suppliers!$A:$A,0)) | E37: Line-haul (rail) | F37: 46226 | G37: 46244 | H37: 46244 | I37: On time | J37: 0 | L37: 5 | M37: 0 | N37: 2595 | O37: =IF(OR(I37="On time",I37="Late",I37="Very late"),1,0) | P37: =IF(AND(O37=1,M37=0),1,0)
A38: GRN52148 | B38: PO18387 | C38: SUP2480 | D38: =INDEX(Suppliers!$B:$B,MATCH(C38,Suppliers!$A:$A,0)) | E38: Supplier's own truck | F38: 46237 | G38: 46244 | H38: 46244 | I38: On time | J38: 0 | L38: 5 | M38: 0 | N38: 3275 | O38: =IF(OR(I38="On time",I38="Late",I38="Very late"),1,0) | P38: =IF(AND(O38=1,M38=0),1,0)
A39: GRN52149 | B39: PO18388 | C39: SUP2189 | D39: =INDEX(Suppliers!$B:$B,MATCH(C39,Suppliers!$A:$A,0)) | E39: Container cartage | F39: 46238 | G39: 46245 | H39: 46245 | I39: On time | J39: 0 | L39: 15 | M39: 0 | N39: 10710 | O39: =IF(OR(I39="On time",I39="Late",I39="Very late"),1,0) | P39: =IF(AND(O39=1,M39=0),1,0)
A40: GRN52150 | B40: PO18389 | C40: SUP2208 | D40: =INDEX(Suppliers!$B:$B,MATCH(C40,Suppliers!$A:$A,0)) | E40: Supplier's own truck | F40: 46234 | G40: 46245 | H40: 46245 | I40: On time | J40: 0 | L40: 4 | M40: 0 | N40: 2780 | O40: =IF(OR(I40="On time",I40="Late",I40="Very late"),1,0) | P40: =IF(AND(O40=1,M40=0),1,0)
A41: GRN52151 | B41: PO18390 | C41: SUP2304 | D41: =INDEX(Suppliers!$B:$B,MATCH(C41,Suppliers!$A:$A,0)) | E41: Supplier's own truck | F41: 46239 | G41: 46245 | H41: 46245 | I41: On time | J41: 0 | L41: 19 | M41: 3 | N41: 6593 | O41: =IF(OR(I41="On time",I41="Late",I41="Very late"),1,0) | P41: =IF(AND(O41=1,M41=0),1,0)
A42: GRN52152 | B42: PO18391 | C42: SUP2422 | D42: =INDEX(Suppliers!$B:$B,MATCH(C42,Suppliers!$A:$A,0)) | E42: Line-haul (rail) | F42: 46230 | G42: 46245 | H42: 46245 | I42: On time | J42: 0 | L42: 8 | M42: 0 | N42: 2496 | O42: =IF(OR(I42="On time",I42="Late",I42="Very late"),1,0) | P42: =IF(AND(O42=1,M42=0),1,0)
A43: GRN52153 | B43: PO18392 | C43: SUP2438 | D43: =INDEX(Suppliers!$B:$B,MATCH(C43,Suppliers!$A:$A,0)) | E43: Line-haul (road) | F43: 46239 | G43: 46245 | H43: 46245 | I43: On time | J43: 0 | L43: 25 | M43: 0 | N43: 11575 | O43: =IF(OR(I43="On time",I43="Late",I43="Very late"),1,0) | P43: =IF(AND(O43=1,M43=0),1,0)
A44: GRN52154 | B44: PO18393 | C44: SUP2480 | D44: =INDEX(Suppliers!$B:$B,MATCH(C44,Suppliers!$A:$A,0)) | E44: Supplier's own truck | F44: 46239 | G44: 46245 | H44: 46245 | I44: On time | J44: 0 | L44: 18 | M44: 0 | N44: 8406 | O44: =IF(OR(I44="On time",I44="Late",I44="Very late"),1,0) | P44: =IF(AND(O44=1,M44=0),1,0)
...
