Workbook
Name Cost_to_raise_a_dollar: 'The fourth sheet'!$B$6
Name Unrestricted_cash_runway: 'The fourth sheet'!$B$7
Name Grants_ending_in_6_months: 'The fourth sheet'!$B$8

Sheet The fourth sheet
A1: The fourth sheet: September 2026 against August 2026
A2: Sample Community Services Ltd · SAMPLE DATA (invented) · The Fourth Sheet · Made with Python (openpyxl)
A3: Data status: Sep 2026 locked (data retrieved 2pm, Tue 6 Oct 2026) · Generated 22 Oct 2026, 4:57pm
A5: Headline number | B5: Sep 2026 | C5: Aug 2026 | D5: Change
A6: Cost to raise a dollar | B6: =Workings!B16 | C6: =Workings!C16 | D6: =B6-C6
A7: Unrestricted cash runway | B7: =Workings!B28 | C7: =Workings!C28 | D7: =B7-C7
A8: Grants ending in 6 months | B8: =Workings!B39
A11: Each grant: over or under budget to 30 September 2026
A12: Spending to date against budget to date (the grant spread evenly over its months). Over budget in red, under budget in green; within 1% in amber.
B13: % of budget | C13: $
A14: Youth outreach | B14: =Workings!B53 | C14: =Workings!B52
A15: Housing support | B15: =Workings!B85 | C15: =Workings!B84
A16: Mental health first aid | B16: =Workings!B111 | C16: =Workings!B110
A17: Digital literacy | B17: =Workings!B134 | C17: =Workings!B133
A18: Community meals | B18: =Workings!B163 | C18: =Workings!B162
A19: Volunteer coordinator | B19: =Workings!B183 | C19: =Workings!B182

Sheet Income and expenditure
A1: Income and expenditure, September 2026
A2: Sample Community Services Ltd · SAMPLE DATA (invented) · The Fourth Sheet · Made with Python (openpyxl)
A3: Data status: Sep 2026 locked (data retrieved 2pm, Tue 6 Oct 2026) · Generated 22 Oct 2026, 4:57pm
A4: $ | B4: Sep 2026 | C4: Aug 2026 | D4: Change
A5: Income
A6: Youth outreach grant | B6: 22800 | C6: 21500 | D6: =B6-C6
A7: Housing support grant | B7: 31200 | C7: 30500 | D7: =B7-C7
A8: Community meals grant | B8: 4300 | C8: 4100 | D8: =B8-C8
A9: Digital literacy grant | B9: 4900 | C9: 5200 | D9: =B9-C9
A10: Mental health first aid grant | B10: 10800 | C10: 9400 | D10: =B10-C10
A11: Volunteer coordinator grant | B11: 3000 | C11: 3000 | D11: =B11-C11
A12: Donations | B12: 27900 | C12: 18400 | D12: =B12-C12
A13: Fundraising events | B13: 41600 | C13: 0 | D13: =B13-C13
A14: Program fees | B14: 28300 | C14: 26800 | D14: =B14-C14
A15: Interest | B15: 1380 | C15: 1450 | D15: =B15-C15
A16: Total income | B16: =SUM(B6:B15) | C16: =SUM(C6:C15) | D16: =B16-C16
A17: Programs
A18: Grant-funded program wages | B18: -57750 | C18: -55275 | D18: =B18-C18
A19: Grant-funded program costs | B19: -19250 | C19: -18425 | D19: =B19-C19
A20: Program delivery wages (untied) | B20: -14500 | C20: -14000 | D20: =B20-C20
A21: Program costs (untied) | B21: -6100 | C21: -5500 | D21: =B21-C21
A22: Total program spend | B22: =SUM(B18:B21) | C22: =SUM(C18:C21) | D22: =B22-C22
A23: Fundraising
A24: Grant writing and reporting | B24: -7100 | C24: -7100 | D24: =B24-C24
A25: Donor campaigns | B25: -5400 | C25: -2200 | D25: =B25-C25
A26: Event costs | B26: -16900 | C26: -2400 | D26: =B26-C26
A27: Total fundraising costs | B27: =SUM(B24:B26) | C27: =SUM(C24:C26) | D27: =B27-C27
A28: Administration
A29: Administration wages | B29: -18300 | C29: -18300 | D29: =B29-C29
A30: Occupancy | B30: -10000 | C30: -10000 | D30: =B30-C30
A31: Other administration | B31: -7600 | C31: -8000 | D31: =B31-C31
A32: Total administration | B32: =SUM(B29:B31) | C32: =SUM(C29:C31) | D32: =B32-C32
A33: Depreciation | B33: -2900 | C33: -2900 | D33: =B33-C33
A34: Total expenses | B34: =B22+B27+B32+B33 | C34: =C22+C27+C32+C33 | D34: =B34-C34
A35: Surplus for the month | B35: =B16+B34 | C35: =C16+C34 | D35: =B35-C35

Sheet Balance sheet
A1: Balance sheet at 30 September 2026
A2: Sample Community Services Ltd · SAMPLE DATA (invented) · The Fourth Sheet · Made with Python (openpyxl)
A3: Data status: Sep 2026 locked (data retrieved 2pm, Tue 6 Oct 2026) · Generated 22 Oct 2026, 4:57pm
A4: $ | B4: Sep 2026 | C4: Aug 2026 | D4: Change
A5: Current assets
A6: Cash at bank | B6: 527060 | C6: 547394 | D6: =B6-C6
A7: Program fees receivable | B7: 11440 | C7: 10780 | D7: =B7-C7
A8: Grants receivable (spent ahead of instalment) | B8: 20900 | C8: 9700 | D8: =B8-C8
A9: Prepayments | B9: 21000 | C9: 21000 | D9: =B9-C9
A10: Total current assets | B10: =SUM(B6:B9) | C10: =SUM(C6:C9) | D10: =B10-C10
A11: Vehicles and equipment | B11: 172200 | C11: 175100 | D11: =B11-C11
A12: Total assets | B12: =B10+B11 | C12: =C10+C11 | D12: =B12-C12
A13: Current liabilities
A14: Payables (bills due next month) | B14: 71775 | C14: 51178 | D14: =B14-C14
A15: Wages owed (since the last pay run) | B15: 36677 | C15: 28711 | D15: =B15-C15
A16: Super payable | B16: 4400 | C16: 3444 | D16: =B16-C16
A17: PAYG withholding payable | B17: 40086 | C17: 26724 | D17: =B17-C17
A18: GST payable (net) | B18: 25437 | C18: 24972 | D18: =B18-C18
A19: Grants received in advance (unspent) | B19: 156100 | C19: 221900 | D19: =B19-C19
A20: Employee leave provisions | B20: 166600 | C20: 165900 | D20: =B20-C20
A21: Total liabilities | B21: =SUM(B14:B20) | C21: =SUM(C14:C20) | D21: =B21-C21
A22: Net assets | B22: =B12-B21 | C22: =C12-C21 | D22: =B22-C22
A23: Equity
A24: Accumulated funds | B24: 251525 | C24: 241145 | D24: =B24-C24

Sheet Cash flow
A1: Cash flow, September 2026
A2: Sample Community Services Ltd · SAMPLE DATA (invented) · The Fourth Sheet · Made with Python (openpyxl)
A3: Data status: Sep 2026 locked (data retrieved 2pm, Tue 6 Oct 2026) · Generated 22 Oct 2026, 4:57pm
A4: $ | B4: Sep 2026 | C4: Aug 2026 | D4: Change
A5: Operating activities
A6: Grant instalments received | B6: 0 | C6: 0 | D6: =B6-C6
A7: Donations and fundraising received | B7: 73660 | C7: 18400 | D7: =B7-C7
A8: Program fees received | B8: 30470 | C8: 28710 | D8: =B8-C8
A9: Interest received | B9: 1380 | C9: 1450 | D9: =B9-C9
A10: Payments to suppliers | B10: -51178 | C10: -36500 | D10: =B10-C10
A11: Payments to employees | B11: -74666 | C11: -74666 | D11: =B11-C11
A12: GST and PAYG paid (BAS) | B12: 0 | C12: 0 | D12: =B12-C12
A13: Net cash from operating activities | B13: =SUM(B6:B12) | C13: =SUM(C6:C12) | D13: =B13-C13
A14: Investing activities
A15: Purchase of vehicles and equipment | B15: 0 | C15: 0 | D15: =B15-C15
A16: Net cash from investing activities | B16: =SUM(B15:B15) | C16: =SUM(C15:C15) | D16: =B16-C16
A17: Net change in cash | B17: =B13+B16 | C17: =C13+C16 | D17: =B17-C17
A18: Cash at start of month | B18: 547394 | C18: 610000 | D18: =B18-C18
A19: Cash at end of month | B19: =B18+B17 | C19: =C18+C17 | D19: =B19-C19

Sheet Grants
A1: Grants at 30 September 2026
A2: Sample Community Services Ltd · SAMPLE DATA (invented) · The Fourth Sheet · Made with Python (openpyxl)
A3: Data status: Sep 2026 locked (data retrieved 2pm, Tue 6 Oct 2026) · Generated 22 Oct 2026, 4:57pm
A4: Budget to date = the grant spread evenly over its months, to 30 September 2026.
A6: Program | B6: Funder | C6: Grant total | D6: Start | E6: End | F6: Received to date | G6: Spent to date | H6: Spent Aug | I6: Spent Sep | J6: Budget to date | K6: Spent against budget | L6: Still to spend | M6: Months left
A7: Youth outreach | B7: State Department of Families | C7: 480000 | D7: 45839 | E7: 46568 | F7: 300000 | G7: 306300 | H7: 21500 | I7: 22800 | J7: 300000 | K7: =IF(J7=0,"",G7/J7) | L7: =C7-G7 | M7: 9
A8: Housing support | B8: State Housing Program | C8: 360000 | D8: 46023 | E8: 46387 | F8: 360000 | G8: 257700 | H8: 30500 | I8: 31200 | J8: 270000 | K8: =IF(J8=0,"",G8/J8) | L8: =C8-G8 | M8: 3
A9: Mental health first aid | B9: Federal health program | C9: 120000 | D9: 46113 | E9: 46477 | F9: 60000 | G9: 57200 | H9: 9400 | I9: 10800 | J9: 60000 | K9: =IF(J9=0,"",G9/J9) | L9: =C9-G9 | M9: 6
A10: Digital literacy | B10: Philanthropic foundation | C10: 90000 | D10: 45931 | E10: 46477 | F10: 45000 | G10: 59600 | H10: 5200 | I10: 4900 | J10: 60000 | K10: =IF(J10=0,"",G10/J10) | L10: =C10-G10 | M10: 6
A11: Community meals | B11: Local council community grant | C11: 48000 | D11: 46204 | E11: 46568 | F11: 48000 | G11: 12000 | H11: 4100 | I11: 4300 | J11: 12000 | K11: =IF(J11=0,"",G11/J11) | L11: =C11-G11 | M11: 9
A12: Volunteer coordinator | B12: State volunteering grant | C12: 36000 | D12: 46082 | E12: 46446 | F12: 36000 | G12: 21000 | H12: 3000 | I12: 3000 | J12: 21000 | K12: =IF(J12=0,"",G12/J12) | L12: =C12-G12 | M12: 5
A13: Total | C13: =SUM(C7:C12) | F13: =SUM(F7:F12) | G13: =SUM(G7:G12) | H13: =SUM(H7:H12) | I13: =SUM(I7:I12) | J13: =SUM(J7:J12) | L13: =SUM(L7:L12)

Sheet Workings
A1: How each number is worked out
A2: Sample Community Services Ltd · SAMPLE DATA (invented) · The Fourth Sheet · Made with Python (openpyxl)
A3: Data status: Sep 2026 locked (data retrieved 2pm, Tue 6 Oct 2026) · Generated 22 Oct 2026, 4:57pm
A5: Cost to raise a dollar
A6: Fundraising costs ÷ money raised (grants, donations, events), in cents
B7: Sep 2026 | C7: Aug 2026
A8: Grant writing and reporting | B8: 7100 | C8: 7100
A9: Donor campaigns | B9: 5400 | C9: 2200
A10: Event costs | B10: 16900 | C10: 2400
A11: Fundraising costs | B11: =B8+B9+B10 | C11: =C8+C9+C10
A12: Grant income | B12: 77000 | C12: 73700
A13: Donations | B13: 27900 | C13: 18400
A14: Fundraising events | B14: 41600 | C14: 0
A15: Money raised | B15: =B12+B13+B14 | C15: =C12+C13+C14
A16: Cost per dollar raised | B16: =B11/B15*100 | C16: =C11/C15*100
A17: September's gala raised $41,600 but cost $16,900 to run, which lifts the month's figure.
A20: Unrestricted cash runway
A21: (Cash at bank − unspent grant money − GST and PAYG owed to the ATO) ÷ a month's cash spending
B22: Sep 2026 | C22: Aug 2026
A23: Cash at bank | B23: 527060 | C23: 547394
A24: Less unspent grant money (belongs to funders' programs) | B24: -156100 | C24: -221900
A25: Less GST and PAYG withheld owed to the ATO (paid with the BAS) | B25: -65523 | C25: -51696
A26: Unrestricted cash | B26: =B23+B24+B25 | C26: =C23+C24+C25
A27: Cash spending in the month (expenses less depreciation) | B27: 162900 | C27: 141200
A28: Runway | B28: =B26/B27 | C28: =C26/C27
A29: Reserves target: 3.0 months.
A32: Grants ending in the next 6 months
A33: Grant total − spent to date, for each grant ending soon
B34: Still to spend
A35: Housing support (ends 31 Dec 2026) | B35: 102300
A36: Digital literacy (ends 31 Mar 2027) | B36: 30400
A37: Mental health first aid (ends 31 Mar 2027) | B37: 62800
A38: Volunteer coordinator (ends 28 Feb 2027) | B38: 15000
A39: Total still to spend | B39: =B35+B36+B37+B38
A40: Unspent money usually has to be returned, or an extension negotiated, so plan the spending now.
A43: Youth outreach
A44: State Department of Families · $480,000 · Jul 2025 to Jun 2027
B45: This grant
A46: Grant total | B46: 480000
A47: Received from the funder | B47: 300000
...

Sheet Assumptions
A1: Assumptions
A2: Sample Community Services Ltd · SAMPLE DATA (invented) · The Fourth Sheet · Made with Python (openpyxl)
A3: Data status: Sep 2026 locked (data retrieved 2pm, Tue 6 Oct 2026) · Generated 22 Oct 2026, 4:57pm
A5: The organisation
A6: What it is | B6: A Brisbane community services charity funded by six grants, donations, events and program fees. About 18 staff. Registered charity, income-tax exempt.
A7: Reporting month | B7: September 2026, compared with August 2026
A8: Financial year | B8: FY2027: 1 July 2026 to 30 June 2027
A10: Grants
A11: Youth outreach | B11: State Department of Families: $480,000, 2025-07 to 2027-06
A12: Housing support | B12: State Housing Program: $360,000, 2026-01 to 2026-12
A13: Community meals | B13: Local council community grant: $48,000, 2026-07 to 2027-06
A14: Digital literacy | B14: Philanthropic foundation: $90,000, 2025-10 to 2027-03
A15: Mental health first aid | B15: Federal health program: $120,000, 2026-04 to 2027-03
A16: Volunteer coordinator | B16: State volunteering grant: $36,000, 2026-03 to 2027-02
A17: Grant income | B17: recognised as the money is spent on the program
A18: Unspent grants | B18: instalments received but not yet spent are a liability (grants received in advance)
A20: Other income and costs
A21: Donations | B21: including the spring appeal in September
A22: Fundraising event | B22: September gala: income and costs in the same month
A23: Grant-funded spending | B23: 75% wages, the rest program costs
A24: Income tax | B24: none: registered charity, income-tax exempt
A26: Cash and balance sheet
A27: Suppliers | B27: paid the following month
A28: Unrestricted cash | B28: cash at bank less unspent grant money, and less GST and PAYG withheld owed to the ATO
A29: Cash runway | B29: unrestricted cash ÷ this month's cash spending
A30: Reserves target | B30: 3 months of spending
A32: GST, BAS and payroll
A33: GST | B33: registered (income over the $150,000 not-for-profit threshold); 10%, accruals basis. The P&L excludes GST; cash, fees receivable and bills include it
A34: BAS | B34: quarterly, self-lodged: GST on sales − GST credits + PAYG withheld. July to September is due 28 October; October to December, 28 February
A35: Pay runs | B35: fortnightly on Thursdays: $39,298 gross (a 26th of the year's gross wages); net pay $32,617 and super $4,716 paid on the day; PAYG withheld (about 17% of gross, $6,681) goes with the BAS. Two months a year have three pay runs
A36: Super | B36: 12% of gross wages, paid with each pay run (Payday Super, from 1 July 2026)
A37: Payroll tax | B37: none: the charity is exempt for wages paid for its charitable work (assumption to confirm)
A38: Banking days | B38: money only moves on banking days: a payment due on a weekend or Queensland public holiday moves to the next banking day
A39: Donations (assumption to confirm) | B39: no GST: a gift isn't payment for anything
A40: Program fees (assumption to confirm) | B40: taxable: GST included in what's charged
A41: Grants (assumption to confirm) | B41: taxable supplies under each funding agreement: the funder pays each instalment plus 10% GST
A42: Fundraising events (assumption to confirm) | B42: taxable: ticket sales include GST
A44: Checks (all passed)
A45: ✓ Every subtotal and total adds up
A46: ✓ Balance sheet balances: assets = liabilities + accumulated funds
...
