Workbook
Name Gross_margin_P_L: 'The fourth sheet'!$B$6
Name Cost_to_win_a_customer: 'The fourth sheet'!$B$7
Name Technician_time_on_jobs: 'The fourth sheet'!$B$8

Sheet The fourth sheet
A1: The fourth sheet: September 2026 against August 2026
A2: Sample Electrical & Air Pty Ltd · SAMPLE DATA (invented) · The Fourth Sheet · Made with Python (openpyxl)
A3: Data status: Sep 2026 locked (data retrieved 2pm, Tue 6 Oct 2026) · Generated 22 Oct 2026, 4:57pm
A5: Headline number | B5: Sep 2026 | C5: Aug 2026 | D5: Change
A6: Gross margin (P&L) | B6: =Workings!B13 | C6: =Workings!C13 | D6: =(B6-C6)*100
A7: Cost to win a customer | B7: =Workings!B22 | C7: =Workings!C22 | D7: =B7-C7
A8: Technician time on jobs | B8: =Workings!B33 | C8: =Workings!C33 | D8: =(B8-C8)*100
A11: Job gross margin on each installation invoiced in September 2026
A12: Whole job, recognised when invoiced: revenue less materials, subcontractors and technician time at $68/hour. Before overheads: not profit. One 35.0% target for every job for now.
B13: Gross margin % | C13: Gross margin $
A14: Bulimba EV chargers | B14: =Workings!B47 | C14: =Workings!B46
A15: Milton office LED lighting | B15: =Workings!B60 | C15: =Workings!B59
A16: Chermside clinic cabling | B16: =Workings!B73 | C16: =Workings!B72
A17: West End cafe air-con | B17: =Workings!B86 | C17: =Workings!B85
A18: Carindale solar and battery | B18: =Workings!B99 | C18: =Workings!B98
A19: Wacol warehouse switchboard | B19: =Workings!B112 | C19: =Workings!B111
A20: Target | B20: 0.35

Sheet Chart lines
A1: Points for the target and break-even lines drawn on the charts (hidden sheet; edit the values on the chart's own sheet).
A3: The fourth sheet: Job gross margin on each installation invoiced in September 2026: Target 35.0%
B4: 0.35 | C4: 0
B5: 0.35 | C5: 1

Sheet Profit and loss
A1: Profit and loss, September 2026
A2: Sample Electrical & Air Pty Ltd · SAMPLE DATA (invented) · The Fourth Sheet · Made with Python (openpyxl)
A3: Data status: Sep 2026 locked (data retrieved 2pm, Tue 6 Oct 2026) · Generated 22 Oct 2026, 4:57pm
A4: $ | B4: Sep 2026 | C4: Aug 2026 | D4: Change
A5: Revenue
A6: Maintenance contracts (14) | B6: 45350 | C6: 45350 | D6: =B6-C6
A7: Installations (jobs) | B7: 146300 | C7: 122800 | D7: =B7-C7
A8: Call-outs: technician time | B8: 24216 | C8: 22338 | D8: =B8-C8
A9: Call-outs: materials charged | B9: 9594 | C9: 9035 | D9: =B9-C9
A10: Total revenue | B10: =SUM(B6:B9) | C10: =SUM(C6:C9) | D10: =B10-C10
A11: Cost of sales
A12: Materials | B12: -64860 | C12: -51530 | D12: =B12-C12
A13: Subcontractors | B13: -13200 | C13: -9300 | D13: =B13-C13
A14: Technician wages (incl. on-costs) | B14: -79587 | C14: -72352 | D14: =B14-C14
A15: Total cost of sales | B15: =SUM(B12:B14) | C15: =SUM(C12:C14) | D15: =B15-C15
A16: Gross profit | B16: =B10+B15 | C16: =C10+C15 | D16: =B16-C16
A17: Operating expenses
A18: Office and admin wages | B18: -21900 | C18: -21900 | D18: =B18-C18
A19: Marketing | B19: -7600 | C19: -8400 | D19: =B19-C19
A20: Vehicles and fuel | B20: -8300 | C20: -7900 | D20: =B20-C20
A21: Rent and occupancy | B21: -7000 | C21: -7000 | D21: =B21-C21
A22: Insurance | B22: -3000 | C22: -3000 | D22: =B22-C22
A23: IT and software | B23: -2300 | C23: -2300 | D23: =B23-C23
A24: Other overheads | B24: -3900 | C24: -3600 | D24: =B24-C24
A25: Total operating expenses | B25: =SUM(B18:B24) | C25: =SUM(C18:C24) | D25: =B25-C25
A26: EBITDA | B26: =B16+B25 | C26: =C16+C25 | D26: =B26-C26
A27: Depreciation | B27: -4500 | C27: -4300 | D27: =B27-C27
A28: Interest | B28: -1080 | C28: -1100 | D28: =B28-C28
A29: Profit before tax | B29: =B26+B27+B28 | C29: =C26+C27+C28 | D29: =B29-C29
A30: Income tax provision (25%) | B30: -2058 | C30: -1710 | D30: =B30-C30
A31: Net profit after tax | B31: =B29+B30 | C31: =C29+C30 | D31: =B31-C31

Sheet Balance sheet
A1: Balance sheet at 30 September 2026
A2: Sample Electrical & Air Pty Ltd · SAMPLE DATA (invented) · The Fourth Sheet · Made with Python (openpyxl)
A3: Data status: Sep 2026 locked (data retrieved 2pm, Tue 6 Oct 2026) · Generated 22 Oct 2026, 4:57pm
A4: $ | B4: Sep 2026 | C4: Aug 2026 | D4: Change
A5: Current assets
A6: Cash at bank | B6: 120228 | C6: 92859 | D6: =B6-C6
A7: Trade debtors (unpaid invoices) | B7: 185678 | C7: 159756 | D7: =B7-C7
A8: Materials on hand | B8: 66000 | C8: 66000 | D8: =B8-C8
A9: Prepayments | B9: 21000 | C9: 21000 | D9: =B9-C9
A10: Total current assets | B10: =SUM(B6:B9) | C10: =SUM(C6:C9) | D10: =B10-C10
A11: Vehicles and equipment | B11: 255200 | C11: 247700 | D11: =B11-C11
A12: Total assets | B12: =B10+B11 | C12: =C10+C11 | D12: =B12-C12
A13: Current liabilities
A14: Trade creditors (bills due next month) | B14: 85866 | C14: 66913 | D14: =B14-C14
A15: Wages owed (since the last pay run) | B15: 37678 | C15: 27458 | D15: =B15-C15
A16: Super payable | B16: 4523 | C16: 3296 | D16: =B16-C16
A17: PAYG withholding payable | B17: 47754 | C17: 31836 | D17: =B17-C17
A18: GST payable (net) | B18: 32817 | C18: 22477 | D18: =B18-C18
A19: Employee leave provisions | B19: 106000 | C19: 105100 | D19: =B19-C19
A20: Income tax payable | B20: 35268 | C20: 33210 | D20: =B20-C20
A21: Total current liabilities | B21: =SUM(B14:B20) | C21: =SUM(C14:C20) | D21: =B21-C21
A22: Equipment finance | B22: 95000 | C22: 100000 | D22: =B22-C22
A23: Total liabilities | B23: =B21+B22 | C23: =C21+C22 | D23: =B23-C23
A24: Net assets | B24: =B12-B23 | C24: =C12-C23 | D24: =B24-C24
A25: Equity
A26: Share capital | B26: 10000 | C26: 10000 | D26: =B26-C26
A27: Retained earnings | B27: 193200 | C27: 187025 | D27: =B27-C27
A28: Total equity | B28: =SUM(B26:B27) | C28: =SUM(C26:C27) | D28: =B28-C28

Sheet Cash flow
A1: Cash flow, September 2026
A2: Sample Electrical & Air Pty Ltd · SAMPLE DATA (invented) · The Fourth Sheet · Made with Python (openpyxl)
A3: Data status: Sep 2026 locked (data retrieved 2pm, Tue 6 Oct 2026) · Generated 22 Oct 2026, 4:57pm
A4: $ | B4: Sep 2026 | C4: Aug 2026 | D4: Change
A5: Operating activities
A6: Receipts from customers (invoices paid) | B6: 222094 | C6: 191442 | D6: =B6-C6
A7: Payments to suppliers | B7: -102223 | C7: -107261 | D7: =B7-C7
A8: Payments to employees | B8: -73222 | C8: -73222 | D8: =B8-C8
A9: Interest paid | B9: -1080 | C9: -1100 | D9: =B9-C9
A10: GST, PAYG and income tax paid (BAS) | B10: 0 | C10: 0 | D10: =B10-C10
A11: Net cash from operating activities | B11: =SUM(B6:B10) | C11: =SUM(C6:C10) | D11: =B11-C11
A12: Investing activities
A13: Purchase of vehicles and equipment | B13: -13200 | C13: 0 | D13: =B13-C13
A14: Net cash from investing activities | B14: =SUM(B13:B13) | C14: =SUM(C13:C13) | D14: =B14-C14
A15: Financing activities
A16: Equipment finance repaid | B16: -5000 | C16: -5000 | D16: =B16-C16
A17: Net cash from financing activities | B17: =SUM(B16:B16) | C17: =SUM(C16:C16) | D17: =B17-C17
A18: Net change in cash | B18: =B11+B14+B17 | C18: =C11+C14+C17 | D18: =B18-C18
A19: Cash at start of month | B19: 92859 | C19: 88000 | D19: =B19-C19
A20: Cash at end of month | B20: =B19+B18 | C20: =C19+C18 | D20: =B20-C20

Sheet Jobs
A1: Jobs, September and August 2026
A2: Sample Electrical & Air Pty Ltd · SAMPLE DATA (invented) · The Fourth Sheet · Made with Python (openpyxl)
A3: Data status: Sep 2026 locked (data retrieved 2pm, Tue 6 Oct 2026) · Generated 22 Oct 2026, 4:57pm
A4: Technician cost rate ($ per hour, wages and all on-costs) | B4: 68
A6: Month | B6: Job | C6: Type | D6: Invoiced | E6: Paid | F6: Revenue | G6: Technician time charged (call-outs) | H6: Materials charged (call-outs) | I6: Materials | J6: Subcontractors | K6: Tech hours | L6: Labour cost (incl. on-costs) | M6: Job gross margin | N6: Job gross margin %
A7: 2026-09 | B7: Call-out CO-49224 | C7: Call-out | D7: 46273 | E7: 46273 | F7: 625 | G7: 326 | H7: 299 | I7: 230 | J7: 0 | K7: 2 | L7: =K7*$B$4 | M7: =F7-I7-J7-L7 | N7: =IF(F7=0,"",M7/F7)
A8: 2026-09 | B8: Call-out CO-49225 | C8: Call-out | D8: 46280 | E8: 46280 | F8: 658 | G8: 489 | H8: 169 | I8: 130 | J8: 0 | K8: 3 | L8: =K8*$B$4 | M8: =F8-I8-J8-L8 | N8: =IF(F8=0,"",M8/F8)
A9: 2026-09 | B9: Call-out CO-49226 | C9: Call-out | D9: 46276 | E9: 46276 | F9: 619 | G9: 489 | H9: 130 | I9: 100 | J9: 0 | K9: 3 | L9: =K9*$B$4 | M9: =F9-I9-J9-L9 | N9: =IF(F9=0,"",M9/F9)
A10: 2026-09 | B10: Call-out CO-49227 | C10: Call-out | D10: 46277 | E10: 46279 | F10: 508 | G10: 326 | H10: 182 | I10: 140 | J10: 0 | K10: 2 | L10: =K10*$B$4 | M10: =F10-I10-J10-L10 | N10: =IF(F10=0,"",M10/F10)
A11: 2026-09 | B11: Call-out CO-49228 | C11: Call-out | D11: 46291 | E11: 46293 | F11: 508 | G11: 326 | H11: 182 | I11: 140 | J11: 0 | K11: 2 | L11: =K11*$B$4 | M11: =F11-I11-J11-L11 | N11: =IF(F11=0,"",M11/F11)
A12: 2026-09 | B12: Call-out CO-49229 | C12: Call-out | D12: 46275 | E12: 46282 | F12: 499 | G12: 408 | H12: 91 | I12: 70 | J12: 0 | K12: 2.5 | L12: =K12*$B$4 | M12: =F12-I12-J12-L12 | N12: =IF(F12=0,"",M12/F12)
A13: 2026-09 | B13: Call-out CO-49231 | C13: Call-out | D13: 46280 | E13: 46294 | F13: 788 | G13: 489 | H13: 299 | I13: 230 | J13: 0 | K13: 3 | L13: =K13*$B$4 | M13: =F13-I13-J13-L13 | N13: =IF(F13=0,"",M13/F13)
A14: 2026-09 | B14: Call-out CO-49232 | C14: Call-out | D14: 46267 | E14: 46269 | F14: 462 | G14: 163 | H14: 299 | I14: 230 | J14: 0 | K14: 1 | L14: =K14*$B$4 | M14: =F14-I14-J14-L14 | N14: =IF(F14=0,"",M14/F14)
A15: 2026-09 | B15: Call-out CO-49233 | C15: Call-out | D15: 46287 | E15: 46317 | F15: 834 | G15: 652 | H15: 182 | I15: 140 | J15: 0 | K15: 4 | L15: =K15*$B$4 | M15: =F15-I15-J15-L15 | N15: =IF(F15=0,"",M15/F15)
A16: 2026-09 | B16: Call-out CO-49234 | C16: Call-out | D16: 46282 | E16: 46286 | F16: 593 | G16: 489 | H16: 104 | I16: 80 | J16: 0 | K16: 3 | L16: =K16*$B$4 | M16: =F16-I16-J16-L16 | N16: =IF(F16=0,"",M16/F16)
A17: 2026-09 | B17: Call-out CO-49235 | C17: Call-out | D17: 46289 | E17: 46296 | F17: 580 | G17: 489 | H17: 91 | I17: 70 | J17: 0 | K17: 3 | L17: =K17*$B$4 | M17: =F17-I17-J17-L17 | N17: =IF(F17=0,"",M17/F17)
A18: 2026-09 | B18: Call-out CO-49236 | C18: Call-out | D18: 46282 | E18: 46289 | F18: 440 | G18: 245 | H18: 195 | I18: 150 | J18: 0 | K18: 1.5 | L18: =K18*$B$4 | M18: =F18-I18-J18-L18 | N18: =IF(F18=0,"",M18/F18)
... A70: 2026-09 | B70: Call-out CO-49298 | C70: Call-out | D70: 46270 | E70: 46279 | F70: 495 | G70: 326 | H70: 169 | I70: 130 | J70: 0 | K70: 2 | L70: =K70*$B$4 | M70: =F70-I70-J70-L70 | N70: =IF(F70=0,"",M70/F70)
A71: 2026-09 | B71: Bulimba EV chargers | C71: Installation | D71: 46288 | E71: 46318 | F71: 11000 | I71: 3600 | J71: 0 | K71: 26 | L71: =K71*$B$4 | M71: =F71-I71-J71-L71 | N71: =IF(F71=0,"",M71/F71)
A72: 2026-09 | B72: Carindale solar and battery | C72: Installation | D72: 46280 | E72: 46294 | F72: 30700 | I72: 13800 | J72: 3100 | K72: 46 | L72: =K72*$B$4 | M72: =F72-I72-J72-L72 | N72: =IF(F72=0,"",M72/F72)
A73: 2026-09 | B73: Chermside clinic cabling | C73: Installation | D73: 46294 | E73: 46324 | F73: 17000 | I73: 4300 | J73: 1800 | K73: 52 | L73: =K73*$B$4 | M73: =F73-I73-J73-L73 | N73: =IF(F73=0,"",M73/F73)
A74: 2026-09 | B74: Milton office LED lighting | C74: Installation | D74: 46274 | E74: 46304 | F74: 20800 | I74: 6900 | J74: 0 | K74: 64 | L74: =K74*$B$4 | M74: =F74-I74-J74-L74 | N74: =IF(F74=0,"",M74/F74)
A75: 2026-09 | B75: Wacol warehouse switchboard | C75: Installation | D75: 46269 | E75: 46314 | F75: 52400 | I75: 22900 | J75: 7400 | K75: 150 | L75: =K75*$B$4 | M75: =F75-I75-J75-L75 | N75: =IF(F75=0,"",M75/F75)
A76: 2026-09 | B76: West End cafe air-con | C76: Installation | D76: 46283 | E76: 46304 | F76: 14400 | I76: 5100 | J76: 900 | K76: 38 | L76: =K76*$B$4 | M76: =F76-I76-J76-L76 | N76: =IF(F76=0,"",M76/F76)
A77: 2026-09 | B77: Ashgrove aged care | C77: Maintenance contract | D77: 46266 | E77: 46296 | F77: 4050 | I77: 80 | J77: 0 | K77: 20 | L77: =K77*$B$4 | M77: =F77-I77-J77-L77 | N77: =IF(F77=0,"",M77/F77)
A78: 2026-09 | B78: Bulimba school | C78: Maintenance contract | D78: 46266 | E78: 46304 | F78: 3150 | I78: 60 | J78: 0 | K78: 16 | L78: =K78*$B$4 | M78: =F78-I78-J78-L78 | N78: =IF(F78=0,"",M78/F78)
A79: 2026-09 | B79: Carindale vet clinic | C79: Maintenance contract | D79: 46266 | E79: 46293 | F79: 1900 | I79: 30 | J79: 0 | K79: 9 | L79: =K79*$B$4 | M79: =F79-I79-J79-L79 | N79: =IF(F79=0,"",M79/F79)
A80: 2026-09 | B80: Chermside retail centre | C80: Maintenance contract | D80: 46266 | E80: 46301 | F80: 4600 | I80: 100 | J80: 0 | K80: 23 | L80: =K80*$B$4 | M80: =F80-I80-J80-L80 | N80: =IF(F80=0,"",M80/F80)
A81: 2026-09 | B81: Fortitude Valley hotel | C81: Maintenance contract | D81: 46266 | E81: 46296 | F81: 3800 | I81: 70 | J81: 0 | K81: 19 | L81: =K81*$B$4 | M81: =F81-I81-J81-L81 | N81: =IF(F81=0,"",M81/F81)
A82: 2026-09 | B82: Kangaroo Point townhouses | C82: Maintenance contract | D82: 46266 | E82: 46304 | F82: 2700 | I82: 50 | J82: 0 | K82: 14 | L82: =K82*$B$4 | M82: =F82-I82-J82-L82 | N82: =IF(F82=0,"",M82/F82)
... A90: 2026-09 | B90: Wynnum medical centre | C90: Maintenance contract | D90: 46266 | E90: 46301 | F90: 2450 | I90: 40 | J90: 0 | K90: 12 | L90: =K90*$B$4 | M90: =F90-I90-J90-L90 | N90: =IF(F90=0,"",M90/F90)
A91: 2026-08 | B91: Call-out CO-49132 | C91: Call-out | D91: 46258 | E91: 46272 | F91: 925 | G91: 652 | H91: 273 | I91: 210 | J91: 0 | K91: 4 | L91: =K91*$B$4 | M91: =F91-I91-J91-L91 | N91: =IF(F91=0,"",M91/F91)
A92: 2026-08 | B92: Call-out CO-49133 | C92: Call-out | D92: 46253 | E92: 46253 | F92: 404 | G92: 326 | H92: 78 | I92: 60 | J92: 0 | K92: 2 | L92: =K92*$B$4 | M92: =F92-I92-J92-L92 | N92: =IF(F92=0,"",M92/F92)
A93: 2026-08 | B93: Call-out CO-49134 | C93: Call-out | D93: 46235 | E93: 46244 | F93: 349 | G93: 245 | H93: 104 | I93: 80 | J93: 0 | K93: 1.5 | L93: =K93*$B$4 | M93: =F93-I93-J93-L93 | N93: =IF(F93=0,"",M93/F93)
A94: 2026-08 | B94: Call-out CO-49135 | C94: Call-out | D94: 46240 | E94: 46240 | F94: 345 | G94: 163 | H94: 182 | I94: 140 | J94: 0 | K94: 1 | L94: =K94*$B$4 | M94: =F94-I94-J94-L94 | N94: =IF(F94=0,"",M94/F94)
A95: 2026-08 | B95: Call-out CO-49136 | C95: Call-out | D95: 46260 | E95: 46267 | F95: 538 | G95: 408 | H95: 130 | I95: 100 | J95: 0 | K95: 2.5 | L95: =K95*$B$4 | M95: =F95-I95-J95-L95 | N95: =IF(F95=0,"",M95/F95)
A96: 2026-08 | B96: Call-out CO-49137 | C96: Call-out | D96: 46245 | E96: 46245 | F96: 606 | G96: 489 | H96: 117 | I96: 90 | J96: 0 | K96: 3 | L96: =K96*$B$4 | M96: =F96-I96-J96-L96 | N96: =IF(F96=0,"",M96/F96)
A97: 2026-08 | B97: Call-out CO-49139 | C97: Call-out | D97: 46247 | E97: 46254 | F97: 189 | G97: 163 | H97: 26 | I97: 20 | J97: 0 | K97: 1 | L97: =K97*$B$4 | M97: =F97-I97-J97-L97 | N97: =IF(F97=0,"",M97/F97)
A98: 2026-08 | B98: Call-out CO-49140 | C98: Call-out | D98: 46237 | E98: 46251 | F98: 749 | G98: 489 | H98: 260 | I98: 200 | J98: 0 | K98: 3 | L98: =K98*$B$4 | M98: =F98-I98-J98-L98 | N98: =IF(F98=0,"",M98/F98)
A99: 2026-08 | B99: Call-out CO-49141 | C99: Call-out | D99: 46255 | E99: 46258 | F99: 860 | G99: 652 | H99: 208 | I99: 160 | J99: 0 | K99: 4 | L99: =K99*$B$4 | M99: =F99-I99-J99-L99 | N99: =IF(F99=0,"",M99/F99)
...

Sheet Workings
A1: How each number is worked out
A2: Sample Electrical & Air Pty Ltd · SAMPLE DATA (invented) · The Fourth Sheet · Made with Python (openpyxl)
A3: Data status: Sep 2026 locked (data retrieved 2pm, Tue 6 Oct 2026) · Generated 22 Oct 2026, 4:57pm
A5: Gross margin (P&L)
A6: Gross profit ÷ revenue. All technician wages and on-costs included; overheads are not.
B7: Sep 2026 | C7: Aug 2026
A8: Revenue (every job invoiced in the month) | B8: 225460 | C8: 199523
A9: Materials | B9: -64860 | C9: -51530
A10: Subcontractors | B10: -13200 | C10: -9300
A11: Technician wages | B11: -79587 | C11: -72352
A12: Gross profit | B12: =B8+B9+B10+B11 | C12: =C8+C9+C10+C11
A13: Gross margin (P&L) | B13: =B12/B8 | C13: =C12/C8
A14: Gross margin is before overheads (office wages, marketing, vehicles, rent and so on): it is not profit. Wages include their on-costs: super (12%) and leave as it's earned. No payroll tax: wages are under Queensland's $1.3 million threshold. Technicians are on salary, so a quiet month for jobs lowers gross margin even if every job is priced well.
A17: Cost to win a customer
A18: Marketing spend ÷ new customers
B19: Sep 2026 | C19: Aug 2026
A20: Marketing spend | B20: 7600 | C20: 8400
A21: New customers (first job ever) | B21: 47 | C21: 41
A22: Cost per new customer | B22: =B20/B21 | C22: =C20/C21
A25: Technician time on jobs
A26: Hours charged to jobs ÷ hours available
B27: Sep 2026 | C27: Aug 2026
A28: Hours charged to jobs (timesheets) | B28: 752.5 | C28: 655
A29: Technicians | B29: 7 | C29: 7
A30: Working days | B30: 22 | C30: 20
A31: Hours per day | B31: 7.6 | C31: 7.6
A32: Hours available | B32: =B29*B30*B31 | C32: =C29*C30*C31
A33: Time on jobs | B33: =B28/B32 | C33: =C28/C32
A34: August had 20 working days: 21 weekdays, less the Ekka People's Day holiday (Wed 12 Aug). The rest is travel, training, quoting and waiting time.
A37: Bulimba EV chargers
A38: Job gross margin ÷ revenue for this job (before overheads)
B39: This job
A40: Revenue | B40: 11000
A41: Materials | B41: -3600
A42: Subcontractors | B42: 0
A43: Technician hours | B43: 26
A44: Technician cost rate ($/hour, wages and all on-costs) | B44: 68
A45: Technician time | B45: =-B43*B44
A46: Job gross margin | B46: =B40+B41+B42+B45
A47: Job gross margin % | B47: =B46/B40
...

Sheet Assumptions
A1: Assumptions
A2: Sample Electrical & Air Pty Ltd · SAMPLE DATA (invented) · The Fourth Sheet · Made with Python (openpyxl)
A3: Data status: Sep 2026 locked (data retrieved 2pm, Tue 6 Oct 2026) · Generated 22 Oct 2026, 4:57pm
A5: The business
A6: What it is | B6: An electrical and air-conditioning contractor in Brisbane: maintenance contracts, installations and call-outs. 7 technicians, 3 office staff.
A7: Reporting month | B7: September 2026 (the last closed month), compared with August 2026
A8: Financial year | B8: FY2027: 1 July 2026 to 30 June 2027
A10: Jobs (September)
A11: Maintenance contracts | B11: 14 customers, invoiced on the 1st, paid in about 30 days
A12: Installations | B12: 6 named jobs, each with its own quote, materials, subcontractors and hours
A13: Call-outs | B13: 64 jobs at $163/hour plus materials marked up 30%
A14: Jobs in September | B14: 84 in total (every one is in the spreadsheet download and CSV)
A16: Costs
A17: Technicians | B17: 7 employed full time: $79,587 in September incl. on-costs (every available hour at $68)
A18: Job costing rate | B18: $68/hour = technician wages incl. on-costs ÷ available hours, worked out each month; time charged to jobs + time not charged = technician wages
A19: Working days | B19: 20 in August (21 weekdays, less the Ekka People's Day holiday, Wed 12 Aug), 22 in September; 7.6 hours a day
A20: Overheads | B20: set month by month, as shown in the P&L
A21: Income tax | B21: 25% of profit, provided monthly; the PAYG instalment is paid with each quarter's BAS
A23: Cash and balance sheet
A24: Customer payments | B24: each invoice is paid on its own date; unpaid invoices at month end = debtors
A25: Supplier bills | B25: materials and subcontractors are paid the following month
A26: Equipment finance | B26: $5,000 repaid each month
A27: New equipment | B27: a $12,000 trailer bought in September
A29: GST, BAS and payroll
A30: GST | B30: registered; 10%, accruals basis: GST on a sale is owed when it's invoiced, a credit on a bill is claimed when it's received. The P&L excludes GST; invoices, bills, debtors, creditors and cash include it
A31: BAS | B31: quarterly, self-lodged: GST on sales − GST credits + PAYG withheld + PAYG instalment. July to September is due 28 October; October to December, 28 February
A32: Pay runs | B32: fortnightly on Thursdays: $39,795 gross (a 26th of the year's gross wages); net pay $31,836 and super $4,775 paid on the day; PAYG withheld (about 20% of gross, $7,959) goes with the BAS. Two months a year have three pay runs
A33: Super | B33: 12% of gross wages, paid with each pay run (Payday Super, from 1 July 2026)
A34: Payroll tax | B34: none: Queensland's threshold is $1.3 million of wages a year (rate 4.75% above it); this business pays about $1,159,000 including super
A35: Banking days | B35: money only moves on banking days: a payment due on a weekend or Queensland public holiday moves to the next banking day
A37: Checks (all passed)
A38: ✓ Every subtotal and total adds up
A39: ✓ Balance sheet balances: assets = liabilities + equity
A40: ✓ Cash flow ends at the cash in the bank
A41: ✓ Profit ties to the movement in retained earnings
A42: ✓ Every job's revenue, materials and subcontractors add up to the P&L
A43: ✓ Trade debtors equal the invoices still unpaid at month end
A45: Print check (done before this file was saved)
A46: ✓ The fourth sheet: 1 page, 100% scale, no block split
A47: ✓ Profit and loss: 1 page, 100% scale, no block split
...
