Workbook
Name December_all_fundraising: 'Report'!$B$10
Name Year_to_date_Jul_to_Dec_2025: 'Report'!$B$11
Name December_Grants: 'Report'!$B$35
Name Year_to_date_Jul_to_Dec_2025_2: 'Report'!$B$36
Name December_Donations: 'Report'!$B$46
Name Year_to_date_Jul_to_Dec_2025_3: 'Report'!$B$47
Name December_Fundraising_events: 'Report'!$B$57
Name Year_to_date_Jul_to_Dec_2025_4: 'Report'!$B$58

Sheet Report
A1: What does it cost to raise a dollar?
A2: Sample Community Services Ltd · SAMPLE DATA (invented) · The Fourth Sheet · Made with Python (openpyxl)
A3: Period: December 2025 · Data status: Dec 2025 locked (data retrieved 2pm, Tue 6 Oct 2026) · Generated 22 Oct 2026, 4:57pm
A5: In short: Each dollar raised cost 14¢ in December, and 14¢ a dollar this financial year to date.
A6: What fundraising costs (grant writing, donor campaigns, events) for every dollar it brings in. Pick a source and every number, chart and note follows it.
A8: Source: All fundraising
A9: Headline number | B9: Value | C9: Compared with
A10: December · all fundraising | B10: =Workings!B10 | C10: November 11¢
A11: Year to date (Jul to Dec 2025) | B11: =Workings!B18 | C11: same period last year: not in the data
A13: Cost to raise a dollar, by source, December 2025 (cents)
B14: Cost to raise a dollar
A15: Grants | B15: 10
A16: Donations | B16: 17
A17: Fundraising events | B17: 42
A27: What it shows
A28: December cost 14¢ to raise each dollar, against 11¢ in November. Fundraising events raised $6,200 and cost $2,600. This financial year to date it has cost 14¢ a dollar.
A30: What you'd do about it
A31: The year-to-date figure is steadier than single months: events make some months jump. Pick a source above to see which one moves it.
A33: Source: Grants
A34: Headline number | B34: Value | C34: Compared with
A35: December · Grants | B35: =Workings!B41 | C35: November 10¢
A36: Year to date (Jul to Dec 2025) | B36: =Workings!B49 | C36: same period last year: not in the data
A38: What it shows
A39: Grants cost 11¢ to raise each dollar this financial year to date ($42,600 of grant writing and reporting for $390,886).
A41: What you'd do about it
A42: Usually the cheapest money to raise, as long as the time that goes into applications and acquittals is protected.
A44: Source: Donations
A45: Headline number | B45: Value | C45: Compared with
A46: December · Donations | B46: =Workings!B58 | C46: November 17¢
A47: Year to date (Jul to Dec 2025) | B47: =Workings!B66 | C47: same period last year: not in the data
A49: What it shows
A50: Donations cost 15¢ to raise each dollar this financial year to date ($16,300 of donor campaigns for $106,600).
A52: What you'd do about it
A53: Steady and cheap, and untied: the money that builds reserves.
A55: Source: Fundraising events
A56: Headline number | B56: Value | C56: Compared with
A57: December · Fundraising events | B57: =Workings!B75 | C57: November none raised
A58: Year to date (Jul to Dec 2025) | B58: =Workings!B84 | C58: same period last year: not in the data
A60: What it shows
A61: Fundraising events cost 41¢ to raise each dollar this financial year to date ($17,800 of event costs for $43,000).
...

Sheet Workings
A1: How each number is worked out
A2: Sample Community Services Ltd · SAMPLE DATA (invented) · The Fourth Sheet · Made with Python (openpyxl)
A3: Period: December 2025 · Data status: Dec 2025 locked (data retrieved 2pm, Tue 6 Oct 2026) · Generated 22 Oct 2026, 4:57pm
A5: Cost to raise a dollar, all fundraising, December and November
A6: Cost of raising it ÷ money raised, in cents
B7: Dec 25 | C7: Nov 25
A8: Cost of raising it | B8: 14100 | C8: 10200
A9: Money raised | B9: 101093 | C9: 88864
A10: Cents per dollar | B10: =B8/B9*100 | C10: =C8/C9*100
A13: Cost to raise a dollar, all fundraising, year to date
A14: Cost ÷ money raised, in cents
B15: Year to date
A16: Cost, year to date | B16: 76700
A17: Raised, year to date | B17: 540486
A18: Cents, year to date | B18: =B16/B17*100
A19: Same period last year: Not available: the data starts October 2024.
A22: Cost to raise a dollar, by source, December 2025
A23: Fundraising cost ÷ money raised, for each source, in cents
B24: Dec 2025
A25: Grants: cost (grant writing and reporting) | B25: 7100
A26: Grants: raised | B26: 68793
A27: Donations: cost (donor campaigns) | B27: 4400
A28: Donations: raised | B28: 26100
A29: Fundraising events: cost (event costs) | B29: 2600
A30: Fundraising events: raised | B30: 6200
A31: Grants: cost per dollar raised | B31: =B25/B26*100
A32: Donations: cost per dollar raised | B32: =B27/B28*100
A33: Fundraising events: cost per dollar raised | B33: =B29/B30*100
A36: Cost to raise a dollar, grants, December and November
A37: Cost of raising it ÷ money raised, in cents
B38: Dec 25 | C38: Nov 25
A39: Cost of raising it | B39: 7100 | C39: 7100
A40: Money raised | B40: 68793 | C40: 70164
A41: Cents per dollar | B41: =B39/B40*100 | C41: =C39/C40*100
A44: Cost to raise a dollar, grants, year to date
A45: Cost ÷ money raised, in cents
B46: Year to date
A47: Cost, year to date | B47: 42600
A48: Raised, year to date | B48: 390886
A49: Cents, year to date | B49: =B47/B48*100
...

Sheet Data
A1: Data
A2: Sample Community Services Ltd · SAMPLE DATA (invented) · The Fourth Sheet · Made with Python (openpyxl)
A3: Period: December 2025 · Data status: Dec 2025 locked (data retrieved 2pm, Tue 6 Oct 2026) · Generated 22 Oct 2026, 4:57pm
A5: Month | B5: Status | C5: Grant writing | D5: Donor campaigns | E5: Event costs | F5: Grant income | G5: Donations | H5: Events | I5: Cents per $1
A6: Oct 24 | B6: Locked | C6: 6500 | D6: 2200 | E6: 0 | F6: 26600 | G6: 15300 | H6: 0 | I6: =IF(SUM(F6:H6)=0,"",SUM(C6:E6)/SUM(F6:H6)*100)
A7: Nov 24 | B7: Locked | C7: 6500 | D7: 3100 | E7: 0 | F7: 31800 | G7: 17700 | H7: 0 | I7: =IF(SUM(F7:H7)=0,"",SUM(C7:E7)/SUM(F7:H7)*100)
A8: Dec 24 | B8: Locked | C8: 6500 | D8: 4400 | E8: 2600 | F8: 29700 | G8: 24700 | H8: 6200 | I8: =IF(SUM(F8:H8)=0,"",SUM(C8:E8)/SUM(F8:H8)*100)
A9: Jan 25 | B9: Locked | C9: 6500 | D9: 2200 | E9: 0 | F9: 62700 | G9: 12400 | H9: 0 | I9: =IF(SUM(F9:H9)=0,"",SUM(C9:E9)/SUM(F9:H9)*100)
A10: Feb 25 | B10: Locked | C10: 6500 | D10: 2200 | E10: 0 | F10: 61700 | G10: 15600 | H10: 0 | I10: =IF(SUM(F10:H10)=0,"",SUM(C10:E10)/SUM(F10:H10)*100)
A11: Mar 25 | B11: Locked | C11: 6500 | D11: 2200 | E11: 0 | F11: 54500 | G11: 15700 | H11: 0 | I11: =IF(SUM(F11:H11)=0,"",SUM(C11:E11)/SUM(F11:H11)*100)
A12: Apr 25 | B12: Locked | C12: 6500 | D12: 2200 | E12: 0 | F12: 61500 | G12: 15700 | H12: 0 | I12: =IF(SUM(F12:H12)=0,"",SUM(C12:E12)/SUM(F12:H12)*100)
A13: May 25 | B13: Locked | C13: 6500 | D13: 2200 | E13: 0 | F13: 61700 | G13: 15800 | H13: 0 | I13: =IF(SUM(F13:H13)=0,"",SUM(C13:E13)/SUM(F13:H13)*100)
A14: Jun 25 | B14: Locked | C14: 6500 | D14: 5500 | E14: 0 | F14: 52200 | G14: 38100 | H14: 0 | I14: =IF(SUM(F14:H14)=0,"",SUM(C14:E14)/SUM(F14:H14)*100)
A15: Jul 25 | B15: Locked | C15: 7100 | D15: 2200 | E15: 0 | F15: 59063 | G15: 13500 | H15: 0 | I15: =IF(SUM(F15:H15)=0,"",SUM(C15:E15)/SUM(F15:H15)*100)
A16: Aug 25 | B16: Locked | C16: 7100 | D16: 2200 | E16: 0 | F16: 61544 | G16: 16000 | H16: 0 | I16: =IF(SUM(F16:H16)=0,"",SUM(C16:E16)/SUM(F16:H16)*100)
A17: Sep 25 | B17: Locked | C17: 7100 | D17: 2200 | E17: 15200 | F17: 62137 | G17: 16100 | H17: 36800 | I17: =IF(SUM(F17:H17)=0,"",SUM(C17:E17)/SUM(F17:H17)*100)
... A20: Dec 25 | B20: Locked | C20: 7100 | D20: 4400 | E20: 2600 | F20: 68793 | G20: 26100 | H20: 6200 | I20: =IF(SUM(F20:H20)=0,"",SUM(C20:E20)/SUM(F20:H20)*100)
