Workbook
Name Services_March_against_March_last_year: 'Report'!$B$16
Name Services_Year_to_date_Jul_to_Mar_2026: 'Report'!$B$17
Name Services_Gross_margin_year_to_date: 'Report'!$B$18
Name Services_March_against_March_last_year_2: 'Report'!$B$28
Name Services_Year_to_date_Jul_to_Mar_2026_2: 'Report'!$B$29
Name Services_Gross_margin_year_to_date_2: 'Report'!$B$30
Name Services_March_against_March_last_year_3: 'Report'!$B$40
Name Services_Year_to_date_Jul_to_Mar_2026_3: 'Report'!$B$41
Name Services_Gross_margin_year_to_date_3: 'Report'!$B$42
Name Services_March_against_March_last_year_4: 'Report'!$B$52
Name Services_Year_to_date_Jul_to_Mar_2026_4: 'Report'!$B$53
Name Services_Gross_margin_year_to_date_4: 'Report'!$B$54

Sheet Report
A1: Which products and services are growing?
A2: Sample Advisory Pty Ltd · SAMPLE DATA (invented) · The Fourth Sheet · Made with Python (openpyxl)
A3: Period: March 2026 · Data status: Mar 2026 locked (data retrieved 2pm, Tue 6 Oct 2026) · Generated 22 Oct 2026, 4:57pm
A5: Revenue, gross margin and growth (year on year) by product or service line over 24 months. Pick a line and every number, chart and note follows it.
A7: Services
A8: From gross margin to profit
A9: March's client work made $80,495 gross margin (66.4%). Consultant time not charged to client work took $24,072 and overheads $51,560, leaving $4,863 profit before tax (4.0% of revenue). To cover overheads, client work needs a 62.4% gross margin on average. (Workings sheet: "From gross margin to profit".)
A11: Gross margin, not profit
A12: Gross margin is not profit. Gross margin = revenue less contractors and consultant time charged to the work at $60 an hour (wages and all on-costs). Not included: consultant time not charged to clients, and overheads (management and admin wages, marketing, rent, IT, insurance, travel, depreciation, interest). Profit is what's left after those. Wages include their on-costs: super (12%) and leave as it's earned. No payroll tax: wages are under Queensland's $1.3 million threshold.
A14: Type of work: All
A15: Headline number | B15: Value | C15: Compared with
A16: March against March last year | B16: =Workings!B27 | C16: $121,215 against $84,340
A17: Year to date (Jul to Mar 2026) | B17: =Workings!B33 | C17: same period last year: not in the data
A18: Gross margin, year to date | B18: =Workings!B43 | C18: $544,845 before overheads
A20: What it shows
A21: Revenue is $810,325 this financial year to date (Jul to Mar 2026). Training makes the highest gross margin (76.4%); Projects the lowest (65.2%). The business needs 62.4% gross margin just to cover overheads.
A23: What you'd do about it
A24: Projects: 65.2% gross margin, 25.2 points over the 40.0% target ($128,735 ahead on $511,425 this financial year to date). Training: 76.4% gross margin, 36.4 points over the 40.0% target ($26,100 ahead on $71,800 this financial year to date).
A26: Type of work: Projects
A27: Headline number | B27: Value | C27: Compared with
A28: March against March last year | B28: =Workings!B51 | C28: $83,115 against $53,340
A29: Year to date (Jul to Mar 2026) | B29: =Workings!B57 | C29: same period last year: not in the data
A30: Gross margin, year to date | B30: =Workings!B67 | C30: $333,305 before overheads
A32: What it shows
A33: Projects brought in $511,425 this financial year to date, at a 65.2% gross margin (below the 67.2% overall).
A35: What you'd do about it
A36: Projects: 65.2% gross margin, 25.2 points over the 40.0% target ($128,735 ahead on $511,425 this financial year to date).
A38: Type of work: Retainers
A39: Headline number | B39: Value | C39: Compared with
A40: March against March last year | B40: =Workings!B75 | C40: $31,100 against $24,000
A41: Year to date (Jul to Mar 2026) | B41: =Workings!B81 | C41: same period last year: not in the data
A42: Gross margin, year to date | B42: =Workings!B91 | C42: $156,720 before overheads
A44: What it shows
A45: Retainers brought in $227,100 this financial year to date, at a 69.0% gross margin (above the 67.2% overall).
A47: What you'd do about it
A48: Retainers: 69.0% gross margin, 29.0 points over the 40.0% target ($65,880 ahead on $227,100 this financial year to date).
A50: Type of work: Training
A51: Headline number | B51: Value | C51: Compared with
A52: March against March last year | B52: =Workings!B99 | C52: $7,000 against $7,000
A53: Year to date (Jul to Mar 2026) | B53: =Workings!B105 | C53: same period last year: not in the data
...

Sheet Workings
A1: How each number is worked out
A2: Sample Advisory Pty Ltd · SAMPLE DATA (invented) · The Fourth Sheet · Made with Python (openpyxl)
A3: Period: March 2026 · Data status: Mar 2026 locked (data retrieved 2pm, Tue 6 Oct 2026) · Generated 22 Oct 2026, 4:57pm
A5: Services: From gross margin to profit, March 2026
A6: Gross margin on the work − time not charged − overheads = profit before tax
B7: Mar 2026
A8: Gross margin on client work | B8: 80495
A9: Consultant wages and on-costs | B9: 60192
A10: Consultant time charged to client work (at cost) | B10: 36120
A11: Consultant time not charged to client work | B11: =B9-B10
A12: Gross profit (the P&L) | B12: =B8-B11
A13: Overheads (operating expenses, depreciation, interest) | B13: 51560
A14: Profit before tax (the P&L) | B14: =B12-B13
A15: Revenue | B15: 121215
A16: Gross margin on client work, % | B16: =B8/B15
A17: Profit before tax, % of revenue | B17: =B14/B15
A18: Gross margin client work need just to cover overheads and time not charged | B18: =(B11+B13)/B15
A19: Ties to the March 2026 P&L (locked). Wages include their on-costs: super (12%) and leave as it's earned. No payroll tax: wages are under Queensland's $1.3 million threshold.
A22: Services, all lines: March against March last year
A23: March 2026 ÷ March 2025 − 1 (year on year)
B24: Mar
A25: Revenue, Mar 2026 | B25: 121215
A26: Revenue, Mar 2025 | B26: 84340
A27: Growth | B27: =B25/B26-1
A30: Services, all lines: year to date
A31: Financial year to date. Not available: the data starts October 2024.
B32: Year to date
A33: Revenue, year to date (Jul to Mar 2026) | B33: 810325
A34: Gross margin, year to date | B34: 544845
A35: Gross margin %, year to date | B35: =B34/B33
A38: Services, all lines: year to date
A39: Financial year to date. Not available: the data starts October 2024.
B40: Year to date
A41: Revenue, year to date (Jul to Mar 2026) | B41: 810325
A42: Gross margin, year to date | B42: 544845
A43: Gross margin %, year to date | B43: =B42/B41
A46: Services, Projects: March against March last year
A47: March 2026 ÷ March 2025 − 1 (year on year)
B48: Mar
A49: Revenue, Mar 2026 | B49: 83115
...

Sheet Data Services
A1: Data Services
A2: Sample Advisory Pty Ltd · SAMPLE DATA (invented) · The Fourth Sheet · Made with Python (openpyxl)
A3: Period: March 2026 · Data status: Mar 2026 locked (data retrieved 2pm, Tue 6 Oct 2026) · Generated 22 Oct 2026, 4:57pm
A5: Line | B5: Month | C5: Status | D5: Revenue | E5: Direct cost | F5: Gross margin | G5: Gross margin %
A6: All | B6: Oct 24 | C6: Locked | D6: 103550 | E6: 35320 | F6: =D6-E6 | G6: =IF(D6=0,"",F6/D6)
A7: All | B7: Nov 24 | C7: Locked | D7: 118390 | E7: 40040 | F7: =D7-E7 | G7: =IF(D7=0,"",F7/D7)
A8: All | B8: Dec 24 | C8: Locked | D8: 125715 | E8: 42940 | F8: =D8-E8 | G8: =IF(D8=0,"",F8/D8)
A9: All | B9: Jan 25 | C9: Locked | D9: 96560 | E9: 33260 | F9: =D9-E9 | G9: =IF(D9=0,"",F9/D9)
A10: All | B10: Feb 25 | C10: Locked | D10: 121275 | E10: 42820 | F10: =D10-E10 | G10: =IF(D10=0,"",F10/D10)
A11: All | B11: Mar 25 | C11: Locked | D11: 84340 | E11: 31940 | F11: =D11-E11 | G11: =IF(D11=0,"",F11/D11)
A12: All | B12: Apr 25 | C12: Locked | D12: 69985 | E12: 25520 | F12: =D12-E12 | G12: =IF(D12=0,"",F12/D12)
A13: All | B13: May 25 | C13: Locked | D13: 104970 | E13: 36100 | F13: =D13-E13 | G13: =IF(D13=0,"",F13/D13)
A14: All | B14: Jun 25 | C14: Locked | D14: 99060 | E14: 35380 | F14: =D14-E14 | G14: =IF(D14=0,"",F14/D14)
A15: All | B15: Jul 25 | C15: Locked | D15: 94805 | E15: 32820 | F15: =D15-E15 | G15: =IF(D15=0,"",F15/D15)
A16: All | B16: Aug 25 | C16: Locked | D16: 67745 | E16: 21360 | F16: =D16-E16 | G16: =IF(D16=0,"",F16/D16)
A17: All | B17: Sep 25 | C17: Locked | D17: 65650 | E17: 20280 | F17: =D17-E17 | G17: =IF(D17=0,"",F17/D17)
... A77: Training | B77: Mar 26 | C77: Locked | D77: 7000 | E77: 2100 | F77: =D77-E77 | G77: =IF(D77=0,"",F77/D77)

Sheet Year to date Services
A1: Year to date Services
A2: Sample Advisory Pty Ltd · SAMPLE DATA (invented) · The Fourth Sheet · Made with Python (openpyxl)
A3: Period: March 2026 · Data status: Mar 2026 locked (data retrieved 2pm, Tue 6 Oct 2026) · Generated 22 Oct 2026, 4:57pm
A5: Line | B5: Year to date | C5: Same period last year | D5: Growth | E5: Gross margin $ | F5: Gross margin %
A6: Projects | B6: 511425 | D6: =IF(C6=0,"",B6/C6-1) | E6: 333305 | F6: =IF(B6=0,"",E6/B6)
A7: Retainers | B7: 227100 | D7: =IF(C7=0,"",B7/C7-1) | E7: 156720 | F7: =IF(B7=0,"",E7/B7)
A8: Training | B8: 71800 | D8: =IF(C8=0,"",B8/C8-1) | E8: 54820 | F8: =IF(B8=0,"",E8/B8)
A9: Total | B9: 810325 | D9: =IF(C9=0,"",B9/C9-1) | E9: 544845 | F9: =IF(B9=0,"",E9/B9)
